Workbook
Name DATA: DATE!$D$2:$D$110
Name DettagliospesegenericheBA: 'Spese Generiche BANCOMAT '!$A:$G
Name DettagliospesegenericheCC: 'Dettaglio Spese Generiche CC'!$A:$G
Name TabellaColori: CATEGORIE!$D$6:$E$17
Name TABELLASPESE: 'Spese Generiche BANCOMAT '!#REF!
Name TABELLASPESE: 'Dettaglio Spese Generiche CC'!#REF!
Name TAGLIARIFORNIMENTO: 'SPESE MENSILI MACCHINA'!$C$37:$C$58

Sheet CATEGORIE
G2: MACRO AREA | H2: TIPOLOGIA | I2: CATEGORIA | J2: FOGLIO
G3: AUTO - SPESE FISSE | H3: SPESE FISSE AUTO | I3: COSTO MOBILITA' | J3: BILANCIO
G4: AUTO - SPESE VARIABILI | H4: SPESE PER LA MACCHINA | I4: COSTO MOBILITA' | J4: ANALISI SPESE GENERICHE CARTA
H5: SPESE PER LA MACCHINA | I5: COSTO MOBILITA' | J5: ANALISI SPESE GENERICHE CONTO
D6: CATEGORIA | E6: COLORE | G6: CARBURANTE | H6: RIFORNIMENTI | I6: COSTO MOBILITA' | J6: BILANCIO
D7: COSTO MOBILITA' | H7: COMMISSIONI RIFORNIMENTI | I7: COSTO MOBILITA' | J7: BILANCIO
D8: COSTO CASA | G8: TRASPORTI E PARCHEGGI | H8: TRASPORTI E PARCHEGGI | I8: COSTO MOBILITA' | J8: ANALISI SPESE GENERICHE CARTA
D9: COSTO SOPRAVVIVENZA | H9: TRASPORTI E PARCHEGGI | I9: COSTO MOBILITA' | J9: ANALISI SPESE GENERICHE CONTO
D10: COSTO ABBONAMENTI | G10: CASA - SPESE FISSE | H10: SPESE FISSE CASA | I10: COSTO CASA | J10: BILANCIO
D11: COSTO SVAGHI (CINEMA&BAR&RISTO) | G11: CASA - SPESE VARIABILI | H11: SPESE PER LA CASA | I11: COSTO CASA | J11: ANALISI SPESE GENERICHE CARTA
D12: COSTO VACANZE | H12: SPESE PER LA CASA | I12: COSTO CASA | J12: ANALISI SPESE GENERICHE CONTO
D13: COSTO SFIZI | H13: SPESE PER L'AFFITTO | I13: COSTO CASA | J13: BILANCIO
D14: MOVIMENTI CONTO | H14: SPESE PER IL GARAGE | I14: COSTO CASA | J14: BILANCIO
D15: TASSE | H15: SPESA GAS | I15: COSTO CASA | J15: BILANCIO
D16: GESTIONE CONTO | H16: SPESA LUCE | I16: COSTO CASA | J16: BILANCIO
D17: RATE GENERICHE | H17: INTERNET | I17: COSTO CASA | J17: BILANCIO
H18: BRICO | I18: COSTO CASA | J18: ANALISI SPESE GENERICHE CARTA
H19: BRICO | I19: COSTO CASA | J19: ANALISI SPESE GENERICHE CONTO
H20: TELEFONO | I20: COSTO SOPRAVVIVENZA
H21: RICARICHE TELEFONICHE | I21: COSTO SOPRAVVIVENZA
H22: SPESE PER LA MACCHINA | I22: COSTO SOPRAVVIVENZA
H23: MACCHINETTA AUTOMATICA | I23: COSTO SOPRAVVIVENZA
H24: COSMETICI | I24: COSTO SOPRAVVIVENZA
H25: MEDICINALI | I25: COSTO SOPRAVVIVENZA
H26: ALIMENTARI | I26: COSTO SOPRAVVIVENZA
H27: VISITE MEDICHE | I27: COSTO SOPRAVVIVENZA
H28: MENSA | I28: COSTO SOPRAVVIVENZA
H29: PROVIDER INTERNET | I29: COSTO SOPRAVVIVENZA
H30: ABBONAMENTI ANNUALI | I30: COSTO ABBONAMENTI
H31: ABBONAMENTI VIDEO MENSILI | I31: COSTO ABBONAMENTI
... H54: RATE MENSILI | I54: RATE GENERICHE

Sheet BILANCIO
B1: PIANO RISPARMI | U1: =MONTH(B2) -> 10
B2: 46296
B3: =CONCATENATE("Spesa Carta ",Valutazioni!E3," €") -> Spesa Carta 2230,93 €
B4: =CONCATENATE("Budget Rimanente ",Valutazioni!I3," €") -> Budget Rimanente 0 €
B5: =CONCATENATE(CONCATENATE("Margine mensile ",YEAR(B2))," ",ROUND(AVERAGEIF(CN71:CQ71,">0"),1)," €") -> Margine mensile 2026 491,8 €
B7: =YEAR(B2) -> 2026 | C7: =IF(YEAR($B$2)=C9,TRUE,FALSE) -> FALSE | D7: =IF(YEAR($B$2)=D9,TRUE,FALSE) -> FALSE | E7: =IF(YEAR($B$2)=E9,TRUE,FALSE) -> FALSE | F7: =IF(YEAR($B$2)=F9,TRUE,FALSE) -> FALSE | G7: =IF(YEAR($B$2)=G9,TRUE,FALSE) -> FALSE | H7: =IF(YEAR($B$2)=H9,TRUE,FALSE) -> FALSE | I7: =IF(YEAR($B$2)=I9,TRUE,FALSE) -> TRUE | K7: =IF(YEAR($B$2)=K9,TRUE,FALSE) -> FALSE | L7: =IF(YEAR($B$2)=L9,TRUE,FALSE) -> FALSE | M7: =IF(YEAR($B$2)=M9,TRUE,FALSE) -> FALSE | N7: =IF(YEAR($B$2)=N9,TRUE,FALSE) -> FALSE | O7: =IF(YEAR($B$2)=O9,TRUE,FALSE) -> FALSE | P7: =IF(YEAR($B$2)=P9,TRUE,FALSE) -> FALSE | Q7: =IF(YEAR($B$2)=Q9,TRUE,FALSE) -> TRUE | S7: =IF($B$2=S9,TRUE,FALSE) -> FALSE | T7: =IF($B$2=T9,TRUE,FALSE) -> FALSE | U7: =IF($B$2=U9,TRUE,FALSE) -> FALSE | V7: =IF($B$2=V9,TRUE,FALSE) -> FALSE | W7: =IF($B$2=W9,TRUE,FALSE) -> FALSE | X7: =IF($B$2=X9,TRUE,FALSE) -> FALSE | Y7: =IF($B$2=Y9,TRUE,FALSE) -> FALSE | Z7: =IF($B$2=Z9,TRUE,FALSE) -> FALSE | ... GT7: =IF($B$2=GT9,TRUE,FALSE) -> FALSE
C8: =IF(C9<=$B$2,1,0) -> 1 | D8: =IF(D9<=$B$2,1,0) -> 1 | E8: =IF(E9<=$B$2,1,0) -> 1 | F8: =IF(F9<=$B$2,1,0) -> 1 | G8: =IF(G9<=$B$2,1,0) -> 1 | H8: =IF(H9<=$B$2,1,0) -> 1 | I8: =IF(I9<=$B$2,1,0) -> 1 | K8: =IF(K9<=$B$2,1,0) -> 1 | L8: =IF(L9<=$B$2,1,0) -> 1 | M8: =IF(M9<=$B$2,1,0) -> 1 | N8: =IF(N9<=$B$2,1,0) -> 1 | O8: =IF(O9<=$B$2,1,0) -> 1 | P8: =IF(P9<=$B$2,1,0) -> 1 | Q8: =IF(Q9<=$B$2,1,0) -> 1 | S8: =IF(S9<=$B$2,1,0) -> 1 | T8: =IF(T9<=$B$2,1,0) -> 1 | U8: =IF(U9<=$B$2,1,0) -> 1 | V8: =IF(V9<=$B$2,1,0) -> 1 | W8: =IF(W9<=$B$2,1,0) -> 1 | X8: =IF(X9<=$B$2,1,0) -> 1 | Y8: =IF(Y9<=$B$2,1,0) -> 1 | Z8: =IF(Z9<=$B$2,1,0) -> 1 | ... GT8: =IF(GT9<=$B$2,1,0) -> 0
C9: 2020 | D9: 2021 | E9: 2022 | F9: 2023 | G9: 2024 | H9: 2025 | I9: 2026 | K9: 2020 | L9: 2021 | M9: 2022 | N9: 2023 | O9: 2024 | P9: 2025 | Q9: 2026 | S9: 43739 | T9: 43770 | U9: 43800 | V9: 43831 | W9: 43862 | X9: 43891 | Y9: 43922 | Z9: 43952 | AA9: 43983 | AB9: 44013 | AC9: 44044 | AD9: 44075 | AE9: 44105 | AF9: 44136 | AG9: 44166 | AH9: 44197 | AI9: 44228 | AJ9: 44256 | AK9: 44287 | AL9: 44317 | AM9: 44348 | AN9: 44378 | AO9: 44409 | AP9: 44440 | AQ9: 44470 | AR9: 44501 | AS9: 44531 | AT9: 44562 | AU9: 44593 | AV9: 44621 | AW9: 44652 | AX9: 44682 | AY9: 44713 | AZ9: 44743 | BA9: 44774 | BB9: 44805 | BC9: 44835 | BD9: 44866 | BE9: 44896 | BF9: 44927 | BG9: 44958 | BH9: 44986 | BI9: 45017 | BJ9: 45047 | BK9: 45078 | BL9: 45108 | BM9: 45139 | BN9: 45170 | BO9: 45200 | BP9: 45231 | BQ9: 45261 | BR9: 45292 | BS9: 45323 | BT9: 45352 | BU9: 45383 | BV9: 45413 | BW9: 45444 | BX9: 45474 | BY9: 45505 | BZ9: 45536 | CA9: 45566 | CB9: 45597 | CC9: 45627 | CD9: 45658 | CE9: 45689 | CF9: 45717 | CG9: 45748 | CH9: 45778 | CI9: 45809 | CJ9: 45839 | CK9: 45870 | CL9: 45901 | CM9: 45931 | CN9: 45962 | CO9: 45992 | CP9: 46023 | CQ9: 46054 | CR9: 46082 | CS9: 46113 | CT9: 46143 | CU9: 46174 | CV9: 46204 | CW9: 46235 | CX9: 46266 | CY9: 46296 | CZ9: 46327 | DA9: 46357 | DB9: 46388 | DC9: 46419 | DD9: 46447 | DE9: 46478 | DF9: 46508 | DG9: 46539 | DH9: 46569 | DI9: 46600 | DJ9: 46631 | DK9: 46661 | DL9: 46692 | DM9: 46722 | DN9: 46753 | DO9: 46784 | DP9: 46813 | DQ9: 46844 | DR9: 46874 | DS9: 46905 | DT9: 46935 | DU9: 46966 | DV9: 46997 | DW9: 47027 | DX9: 47058 | DY9: 47088 | DZ9: 47119 | EA9: 47150 | EB9: 47178 | EC9: 47209 | ED9: 47239 | EE9: 47270 | EF9: 47300 | EG9: 47331 | EH9: 47362 | EI9: 47392 | EJ9: 47423 | EK9: 47453 | EL9: 47484 | EM9: 47515 | EN9: 47543 | EO9: 47574 | EP9: 47604 | EQ9: 47635 | ER9: 47665 | ES9: 47696 | ET9: 47727 | EU9: 47757 | EV9: 47788 | EW9: 47818 | EX9: 47849 | EY9: 47880 | EZ9: 47908 | FA9: 47939 | FB9: 47969 | FC9: 48000 | FD9: 48030 | FE9: 48061 | FF9: 48092 | FG9: 48122 | FH9: 48153 | FI9: 48183 | FJ9: 48214 | FK9: 48245 | FL9: 48274 | FM9: 48305 | FN9: 48335 | FO9: 48366 | FP9: 48396 | FQ9: 48427 | FR9: 48458 | FS9: 48488 | FT9: 48519 | FU9: 48549 | FV9: 48580 | FW9: 48611 | FX9: 48639 | FY9: 48670 | FZ9: 48700 | GA9: 48731 | GB9: 48761 | GC9: 48792 | GD9: 48823 | GE9: 48853 | GF9: 48884 | GG9: 48914 | GH9: 48945 | GI9: 48976 | GJ9: 49004 | GK9: 49035 | GL9: 49065 | GM9: 49096 | GN9: 49126 | GO9: 49157 | GP9: 49188 | GQ9: 49218 | GR9: 49249 | GS9: 49279 | GT9: 49310
B10: RIMANENZA INIZIALE | C10: =U32 -> 11552.48 | D10: =C35 -> 2224.51 | E10: =D35 -> 4838.61 | F10: =E35 -> 3883.43 | G10: =F35 -> 3214.45 | H10: =G35 -> 8487.16 | I10: =H35 -> 11614.742 | K10: MEDIA ANNUA CONTO | S10: 7395.16 | T10: =S32 -> 7851.23 | U10: =T32 -> 8195.8 | V10: =U32 -> 11552.48 | W10: =V32 -> 11541.37 | X10: =W32 -> 11543.58 | Y10: =X32 -> 11517.65 | Z10: =Y32 -> 11874.52 | AA10: =Z32 -> 12417.52 | ... GT10: =GS32 -> 122399.15
B11: STIPENDIO MENSILE | C11: =SUM(V11:AG11) -> 26686 | D11: =SUM(AH11:AS11) -> 26628 | E11: =SUM(AT11:BE11) -> 27484 | F11: =SUM(BF11:BQ11) -> 27474 | G11: =SUM(BR11:CC11) -> 30103 | H11: =SUM(CD11:CO11) -> 30235 | I11: =SUM(CP11:DA11) -> 32872 | K11: =C11/12 -> 2223.8333 | L11: =D11/12 -> 2219 | M11: =E11/12 -> 2290.3333 | N11: =F11/12 -> 2289.5 | O11: =G11/12 -> 2508.5833 | P11: =H11/12 -> 2519.5833 | Q11: =I11/12 -> 2739.3333 | S11: 2158 | T11: 2222 | U11: =2271 -> 2271 | V11: 2741 | W11: 2166 | X11: 2175 | Y11: 2158 | Z11: 2157 | AA11: 2158 | AB11: 2156 | AC11: 2169 | AD11: 2098 | AE11: 2167 | AF11: 2168 | AG11: =2373 -> 2373 | AH11: 1827 | AI11: 2177 | AJ11: 2165 | AK11: 2170 | AL11: 2227 | AM11: 2168 | AN11: 2167 | AO11: =2167+539 -> 2706 | AP11: =2379 -> 2379 | AQ11: 2164 | AR11: 2166 | AS11: =2312 -> 2312 | AT11: =2308 -> 2308 | AU11: 2249 | AV11: 2238 | AW11: 2250 | AX11: 2243 | AY11: 2314 | AZ11: 2242 | BA11: 2244 | BB11: =2519 -> 2519 | BC11: 2238 | BD11: =2248 -> 2248 | BE11: =2391 -> 2391 | BF11: 2078 | BG11: =2294 -> 2294 | BH11: 2245 | BI11: 2251 | BJ11: 2250 | BK11: 2251 | BL11: 2326 | BM11: 2327 | BN11: 2325 | BO11: =BN11 -> 2325 | BP11: 2327 | BQ11: =2475 -> 2475 | BR11: 3111 | BS11: =2425 -> 2425 | BT11: 2373 | BU11: 2373 | BV11: =BU11 -> 2373 | BW11: =2385 -> 2385 | BX11: 2541 | BY11: =2394 -> 2394 | BZ11: 2389 | CA11: 2538 | CB11: 2429 | CC11: =2772 -> 2772 | CD11: 3117 | CE11: 2538 | CF11: =CB11 -> 2429 | CG11: 2506 | CH11: 2506 | CI11: 2411 | CJ11: 2430 | CK11: 2367 | CL11: 2430 | CM11: 2430 | CN11: 2461 | CO11: 2610 | CP11: 3012 | CQ11: 2497 | CR11: 2486 | CS11: =CR11 -> 2486 | CT11: 2486 | CU11: 2636 | CV11: =2638 -> 2638 | CW11: 3488 | CX11: 3229 | CY11: =CV11 -> 2638 | CZ11: =CY11 -> 2638 | DA11: =CZ11 -> 2638 | DB11: =CZ11 -> 2638 | DC11: =DB11 -> 2638 | DD11: =DC11 -> 2638 | DE11: =DD11 -> 2638 | DF11: =DE11 -> 2638 | DG11: =DF11 -> 2638 | DH11: =DG11 -> 2638 | DI11: =DH11 -> 2638 | DJ11: =DI11 -> 2638 | ... DM11: =DL11 -> 2638 | DN11: =DL11 -> 2638 | DO11: =DN11 -> 2638 | DP11: =DO11 -> 2638 | DQ11: =DP11 -> 2638 | DR11: =DQ11 -> 2638 | DS11: =DR11 -> 2638 | DT11: =DS11 -> 2638 | DU11: =DT11 -> 2638 | DV11: =DU11 -> 2638 | ... DY11: =DX11 -> 2638 | DZ11: =DX11 -> 2638 | EA11: =DZ11 -> 2638 | EB11: =EA11 -> 2638 | EC11: =EB11 -> 2638 | ED11: =EC11 -> 2638 | EE11: =ED11 -> 2638 | EF11: =EE11 -> 2638 | EG11: =EF11 -> 2638 | EH11: =EG11 -> 2638 | ... EK11: =EJ11 -> 2638 | EL11: =EJ11 -> 2638 | EM11: =EL11 -> 2638 | EN11: =EM11 -> 2638 | EO11: =EN11 -> 2638 | EP11: =EO11 -> 2638 | EQ11: =EP11 -> 2638 | ER11: =EQ11 -> 2638 | ES11: =ER11 -> 2638 | ET11: =ES11 -> 2638 | ... GT11: =GS11 -> 2638
B12: TREDICESIMA + PREMIO (MBO) | C12: =SUM(V12:AG12) -> 5791 | D12: =SUM(AH12:AS12) -> 3290 | E12: =SUM(AT12:BE12) -> 3871 | F12: =SUM(BF12:BQ12) -> 2332 | G12: =SUM(BR12:CC12) -> 6240 | H12: =SUM(CD12:CO12) -> 5937 | I12: =SUM(CP12:DA12) -> 50120.05 | K12: =C12/12 -> 482.58333 | L12: =D12/12 -> 274.16667 | M12: =E12/12 -> 322.58333 | N12: =F12/12 -> 194.33333 | O12: =G12/12 -> 520 | P12: =IFERROR(SUM(CD12:CO12)/12,0) -> 494.75 | Q12: =IFERROR(SUM(CP12:DA12)/12,0) -> 4176.6708 | U12: 3525 | AG12: =2500+3291 -> 5791 | AS12: 3290 | BE12: 3871 | BQ12: 2332 | BT12: 3613 | CC12: 2627 | CF12: 3313 | CO12: 2624 | CS12: 3428 | CT12: =8581.07 -> 8581.07 | CU12: 35680.98 | DA12: 2430 | DM12: 2430 | DY12: 2430 | EK12: 2430 | EW12: 2430 | FI12: 2430 | FU12: 2430 | GG12: 2430 | GS12: 2430
B13: TOTALE STIPENDIO | C13: =C11+C12 -> 32477 | D13: =D11+D12 -> 29918 | E13: =E11+E12 -> 31355 | F13: =F11+F12 -> 29806 | G13: =G11+G12 -> 36343 | H13: =H11+H12 -> 36172 | I13: =I11+I12 -> 82992.05 | K13: =C13/12 -> 2706.4167 | L13: =D13/12 -> 2493.1667 | M13: =E13/12 -> 2612.9167 | N13: =F13/12 -> 2483.8333 | O13: =G13/12 -> 3028.5833 | P13: =H13/12 -> 3014.3333 | Q13: =Q11+Q12 -> 6916.0042 | CB13: =CB11+CB12 -> 2429 | CC13: =CC11+CC12 -> 5399 | CD13: =CD11+CD12 -> 3117 | CE13: =CE11+CE12 -> 2538 | CF13: =CF11+CF12 -> 5742 | CG13: =CG11+CG12 -> 2506 | CH13: =CH11+CH12 -> 2506 | CI13: =CI11+CI12 -> 2411 | ... GT13: =GT11+GT12 -> 2638
B14: SITUAZIONE CONTO IN BANCA | D14: =(D11-C11)/C11 -> -0.0021734243 | E14: =(E11-D11)/D11 -> 0.032146613 | F14: =(F11-E11)/E11 -> -0.00036384806 | G14: =(G11-F11)/F11 -> 0.095690471 | H14: =(H11-G11)/G11 -> 0.004384945 | I14: =(I11-H11)/H11 -> 0.087216802 | S14: =S10+S11 -> 9553.16 | T14: =T10+T11 -> 10073.23 | U14: =U10+U11 -> 10466.8 | V14: =V10+V11 -> 14293.48 | W14: =W10+W11 -> 13707.37 | X14: =X10+X11 -> 13718.58 | Y14: =Y10+Y11 -> 13675.65 | Z14: =Z10+Z11 -> 14031.52 | ... GT14: =GT10+GT11 -> 125037.15
B15: - SPESA AFFITTO | E15: =SUM(AT15:BE15) -> 0 | F15: =SUM(AJ15:AU15) -> 0 | G15: =SUM(AK15:AV15) -> 0 | H15: =SUM(AL15:AW15) -> 0 | I15: =SUM(AM15:AX15) -> 0 | S15: 420.5 | T15: 420.5 | U15: 420.5 | V15: 420.5 | W15: 420.5 | X15: 420.5 | Y15: 420.5 | Z15: 420.5 | AA15: 420.5 | AB15: 420.5 | AC15: 420.5 | AD15: 420.5 | AE15: 420.5 | AF15: 420.5 | AG15: 420.5 | AH15: 420.5
B16: - SPESE FISSE CASA | C16: =SUM(V16:AG16)+SUM(V17:AG17)+SUM(V15:AG15) -> 17059.5 | D16: =SUM(AH16:AS16)+SUM(AH17:AS17)+SUM(AH15:AS15) -> 8286 | E16: =SUM(AT16:BE16) -> 29295 | F16: =SUM(BF16:BQ16) -> 10606 | G16: =SUM(BR16:CC16) -> 10231 | H16: =SUM(CD16:CO16) -> 8760 | I16: =SUM(CP16:DA16) -> 9966 | K16: =C16/12 -> 1421.625 | L16: =D16/12 -> 690.5 | M16: =E16/12 -> 2441.25 | N16: =F16/12 -> 883.83333 | O16: =G16/12 -> 852.58333 | P16: =H16/12 -> 730 | Q16: =IFERROR(AVERAGEIF(CP16:DA16,">0"),0) -> 830.5 | AF16: 11003 | AG16: =350.5 -> 350.5 | AI16: 500.5 | AJ16: 350.5 | AK16: 500.5 | AL16: 500.5 | AM16: 600.5 | AN16: 550.5 | AO16: 900.5 | AP16: 950.5 | AQ16: 1000.5 | AR16: 950.5 | AS16: 1000.5 | AT16: =50.5+845.5 -> 896 | AU16: 870.5 | AV16: 600.5 | AW16: 700.5 | AX16: 820.5 | AY16: 700.5 | AZ16: =820.5+50.5+200.5 -> 1071.5 | BA16: 870.5 | BB16: =BA16+19002.5 -> 19873 | BC16: =870.5 -> 870.5 | BD16: =BC16 -> 870.5 | BE16: =1150.5 -> 1150.5 | BF16: 820.5 | BG16: 870.5 | BH16: =BG16 -> 870.5 | BI16: 850.5 | BJ16: =BH16 -> 870.5 | BK16: =BJ16 -> 870.5 | BL16: =BK16 -> 870.5 | BM16: =BL16 -> 870.5 | BN16: =BM16 -> 870.5 | BO16: =BN16 -> 870.5 | BP16: =BO16 -> 870.5 | BQ16: 1100.5 | BR16: 870 | BS16: =819.5+0.5 -> 820 | BT16: =849.5+0.5 -> 850 | BU16: =785+0.5 -> 785.5 | BV16: =859.5+0.5 -> 860 | BW16: =BV16 -> 860 | BX16: =BW16 -> 860 | BY16: =BX16 -> 860 | BZ16: =BY16 -> 860 | CA16: =BZ16 -> 860 | CB16: =859.5+0.5 -> 860 | CC16: =825+59.5+0.5+0.5 -> 885.5 | CD16: =(749.5+0.5)+(99.5+0.5) -> 850 | CE16: =799.5+0.5 -> 800 | CF16: =739.5+0.5 -> 740 | CG16: =CF16-60 -> 680 | CH16: =CF16 -> 740 | CI16: =679.5+0.5 -> 680 | CJ16: =639.5+0.5 -> 640 | CK16: =740 -> 740 | CL16: =640 -> 640 | CM16: =770 -> 770 | CN16: 700 | CO16: 780 | CP16: 780 | CQ16: 500 | CR16: 850 | CS16: =700 -> 700 | CT16: =699.5+0.5 -> 700 | CU16: 700 | CV16: 750 | CW16: =740 -> 740 | CX16: =685.5+1340.5 -> 2026 | CY16: 740 | CZ16: =CY16 -> 740 | DA16: =CZ16 -> 740 | DB16: =DA16 -> 740 | DC16: =DB16 -> 740 | DD16: =DC16 -> 740 | DE16: =DD16 -> 740 | DF16: =DE16 -> 740 | DG16: =DF16 -> 740 | ... GT16: =GS16 -> 740
B17: - SPESA GARAGE | E17: =SUM(AT17:BE17) -> 0 | F17: =SUM(BF17:BQ17) -> 0 | G17: =SUM(BR17:CC17) -> 0 | H17: =SUM(CD17:CO17) -> 0 | I17: =SUM(CE17:CP17) -> 0 | Q17: =IFERROR(AVERAGEIF(CE17:CP17,">0"),0) -> 0 | W17: 180 | Z17: 180 | AC17: 180 | AF17: 60 | AG17: 60 | AH17: 60
B18: - SPESE FISSE AUTO | C18: =SUM(V18:AG18) -> 3564 | D18: =SUM(AH18:AS18) -> 3568.5 | E18: =SUM(AT18:BE18) -> 16885.23 | F18: =SUM(BF18:BQ18) -> 3259 | G18: =SUM(BR18:CC18) -> 3259 | H18: =SUM(CD18:CO18) -> 3259 | I18: =SUM(CP18:DA18) -> 3259 | K18: =C18/12 -> 297 | L18: =D18/12 -> 297.375 | M18: =E18/12 -> 1407.1025 | N18: =F18/12 -> 271.58333 | O18: =G18/12 -> 271.58333 | P18: =H18/12 -> 271.58333 | Q18: =IFERROR(AVERAGEIF(CP18:DA18,">0"),0) -> 271.58333 | S18: 297 | T18: 297 | U18: 297 | V18: 297 | W18: 297 | X18: 297 | Y18: 297 | Z18: 297 | AA18: 297 | AB18: 297 | AC18: 297 | AD18: 297 | AE18: 297 | AF18: 297 | AG18: 297 | AH18: 297 | AI18: 297 | AJ18: 297 | AK18: 297.5 | AL18: 297.5 | AM18: 297.5 | AN18: 297.5 | AO18: 297.5 | AP18: 297.5 | AQ18: 297.5 | AR18: 297.5 | AS18: 297.5 | AT18: 297.5 | AU18: =199+2.75+0.5+13838.98 -> 14041.23 | AV18: =185.75+2.5 -> 188.25 | AW18: =AV18 -> 188.25 | AX18: =AW18+83 -> 271.25 | AY18: =AX18 -> 271.25 | AZ18: =AY18 -> 271.25 | BA18: =80.5+2.5+185.75+2.5 -> 271.25 | BB18: =BA18 -> 271.25 | BC18: =BB18 -> 271.25 | BD18: =BC18 -> 271.25 | BE18: =BD18 -> 271.25 | BF18: =BE18 -> 271.25 | BG18: =BF18 -> 271.25 | BH18: =BG18 -> 271.25 | BI18: ='SPESE MENSILI MACCHINA'!P50 -> 275.25 | BJ18: =BH18 -> 271.25 | BK18: =BJ18 -> 271.25 | BL18: =BK18 -> 271.25 | BM18: =BL18 -> 271.25 | BN18: =BM18 -> 271.25 | BO18: ='SPESE MENSILI MACCHINA'!P56 -> 271.25 | BP18: =BO18 -> 271.25 | BQ18: =BP18 -> 271.25 | BR18: =BQ18 -> 271.25 | BS18: =BR18 -> 271.25 | BT18: =BS18 -> 271.25 | BU18: =275.25 -> 275.25 | BV18: 271.25 | BW18: =BV18 -> 271.25 | BX18: =BW18 -> 271.25 | BY18: =BX18 -> 271.25 | BZ18: =BY18 -> 271.25 | CA18: =BZ18 -> 271.25 | CB18: =CA18 -> 271.25 | CC18: =CB18 -> 271.25 | CD18: =CC18 -> 271.25 | ... CF18: =CE18 -> 271.25 | CG18: 275.25 | CH18: =CF18 -> 271.25 | CI18: =CH18 -> 271.25 | CJ18: =CI18 -> 271.25 | CK18: =CJ18 -> 271.25 | CL18: =CK18 -> 271.25 | CM18: =CL18 -> 271.25 | CN18: =CM18 -> 271.25 | CO18: =CN18 -> 271.25 | CP18: =CO18 -> 271.25 | ... CR18: =CQ18 -> 271.25 | CS18: =275.25 -> 275.25 | CT18: =CR18 -> 271.25 | CU18: =CT18 -> 271.25 | CV18: =CU18 -> 271.25 | CW18: =CV18 -> 271.25 | CX18: =CW18 -> 271.25 | CY18: =CX18 -> 271.25 | CZ18: =CY18 -> 271.25 | DA18: =CZ18 -> 271.25 | DB18: =DA18 -> 271.25 | ... DT18: =DS18 -> 271.25 | DU18: =DT18-('Gestione finanziamenti'!K10) -> 188.25 | DV18: =DU18 -> 188.25 | DW18: =DV18 -> 188.25 | DX18: =DW18 -> 188.25 | DY18: =DX18 -> 188.25 | DZ18: =DY18 -> 188.25 | EA18: =DZ18 -> 188.25 | EB18: =EA18 -> 188.25 | EC18: =EB18 -> 188.25 | ... FT18: =FS18 -> 188.25
B19: - SPESA ASSICURAZIONE | C19: =SUM(V19:AG19) -> 539.89 | D19: =SUM(AH19:AS19) -> 531.89 | E19: =SUM(AT19:BE19) -> 589.84 | F19: =SUM(BF19:BQ19) -> 380 | G19: =SUM(BR19:CC19) -> 0 | H19: =SUM(CD19:CO19) -> 0 | I19: =SUM(CP19:DA19) -> 0 | K19: =C19/12 -> 44.990833 | L19: =D19/12 -> 44.324167 | M19: =E19/12 -> 49.153333 | N19: =F19/12 -> 31.666667 | O19: =G19/12 -> 0 | P19: =H19/12 -> 0 | Q19: =IFERROR(AVERAGEIF(CE19:CP19,">0"),0) -> 0 | S19: 53.93 | T19: 53.93 | U19: 53.93 | V19: 53.93 | W19: 53.93 | X19: 53.93 | Y19: 53.93 | Z19: 54.02 | AC19: 54.03 | AD19: 54.03 | AE19: 54.03 | AF19: 54.03 | AG19: 54.03 | AH19: 54.03 | AJ19: =54.03+54.03 -> 108.06 | AK19: 54.53 | AL19: 54.62 | AO19: 52.13 | AP19: 52.13 | AQ19: 52.13 | AR19: 52.13 | AS19: 52.13 | AT19: =53.23+2.5 -> 55.73 | AU19: 52.13 | AV19: 52.13 | AW19: 52.13 | AX19: 52.22 | AZ19: 325.5 | BL19: 380
B20: -COMMISSIONI CANONE MENSILE | C20: =SUM(V20:AG20) -> 66 | D20: =SUM(AH20:AS20) -> 112.35 | E20: =SUM(AT20:BE20) -> 82.2 | F20: =SUM(BF20:BQ20) -> 82.2 | G20: =SUM(BR20:CC20) -> 82.2 | H20: =SUM(CD20:CO20) -> 82.2 | I20: =SUM(CP20:DA20) -> 82.2 | K20: =C20/12 -> 5.5 | L20: =D20/12 -> 9.3625 | M20: =E20/12 -> 6.85 | N20: =F20/12 -> 6.85 | O20: =G20/12 -> 6.85 | P20: =H20/12 -> 6.85 | Q20: =IFERROR(AVERAGEIF(CP20:DA20,">0"),0) -> 6.85 | S20: 5.5 | T20: 5.5 | U20: 5.5 | V20: 5.5 | W20: 5.5 | X20: 5.5 | Y20: 5.5 | Z20: 5.5 | AA20: 5.5 | AB20: 5.5 | AC20: 5.5 | AD20: 5.5 | AE20: 5.5 | AF20: 5.5 | AG20: 5.5 | AH20: =5.5+34.2 -> 39.7 | AI20: 5.5 | AJ20: 5.5 | AK20: 6.85 | AL20: 6.85 | AM20: 6.85 | AN20: 6.85 | AO20: 6.85 | AP20: 6.85 | AQ20: 6.85 | AR20: 6.85 | AS20: 6.85 | AT20: 6.85 | AU20: 6.85 | AV20: 6.85 | AW20: 6.85 | AX20: 6.85 | AY20: 6.85 | AZ20: 6.85 | BA20: 6.85 | BB20: 6.85 | BC20: 6.85 | BD20: 6.85 | BE20: 6.85 | BF20: 6.85 | BG20: 6.85 | BH20: 6.85 | BI20: 6.85 | BJ20: 6.85 | BK20: 6.85 | BL20: 6.85 | BM20: 6.85 | BN20: 6.85 | BO20: 6.85 | BP20: 6.85 | BQ20: 6.85 | BR20: 6.85 | BS20: 6.85 | BT20: 6.85 | BU20: 6.85 | BV20: 6.85 | BW20: 6.85 | BX20: 6.85 | BY20: 6.85 | BZ20: 6.85 | CA20: 6.85 | CB20: 6.85 | CC20: 6.85 | CD20: 6.85 | CE20: 6.85 | CF20: 6.85 | CG20: 6.85 | CH20: 6.85 | CI20: 6.85 | CJ20: 6.85 | CK20: 6.85 | CL20: 6.85 | CM20: 6.85 | CN20: 6.85 | CO20: 6.85 | CP20: 6.85 | CQ20: 6.85 | CR20: 6.85 | CS20: 6.85 | CT20: 6.85 | CU20: 6.85 | CV20: 6.85 | CW20: 6.85 | CX20: 6.85 | CY20: 6.85 | CZ20: 6.85 | DA20: 6.85 | DB20: 6.85 | DC20: 6.85 | DD20: 6.85 | DE20: 6.85 | DF20: 6.85 | DG20: 6.85 | DH20: 6.85 | DI20: 6.85 | DJ20: 6.85 | DK20: 6.85 | DL20: 6.85 | DM20: 6.85 | DN20: 6.85 | DO20: 6.85 | DP20: 6.85 | DQ20: 6.85 | DR20: 6.85 | DS20: 6.85 | DT20: 6.85 | DU20: 6.85 | DV20: 6.85 | DW20: 6.85 | DX20: 6.85 | DY20: 6.85 | DZ20: 6.85 | EA20: 6.85 | EB20: 6.85 | EC20: 6.85 | ED20: 6.85 | EE20: 6.85 | EF20: 6.85 | EG20: 6.85 | EH20: 6.85 | EI20: 6.85 | EJ20: 6.85 | EK20: 6.85 | EL20: 6.85 | EM20: 6.85 | EN20: 6.85 | EO20: 6.85 | EP20: 6.85 | EQ20: 6.85 | ER20: 6.85 | ES20: 6.85 | ET20: 6.85 | EU20: 6.85 | EV20: 6.85 | EW20: 6.85 | EX20: 6.85 | EY20: 6.85 | EZ20: 6.85 | FA20: 6.85 | FB20: 6.85 | FC20: 6.85 | FD20: 6.85 | FE20: 6.85 | FF20: 6.85 | FG20: 6.85 | FH20: 6.85 | FI20: 6.85 | FJ20: 6.85 | FK20: 6.85 | FL20: 6.85 | FM20: 6.85 | FN20: 6.85 | FO20: 6.85 | FP20: 6.85 | FQ20: 6.85 | FR20: 6.85 | FS20: 6.85 | FT20: 6.85 | FU20: 6.85 | FV20: 6.85 | FW20: 6.85 | FX20: 6.85 | FY20: 6.85 | FZ20: 6.85 | GA20: 6.85 | GB20: 6.85 | GC20: 6.85 | GD20: 6.85 | GE20: 6.85 | GF20: 6.85 | GG20: 6.85 | GH20: 6.85 | GI20: 6.85 | GJ20: 6.85 | GK20: 6.85 | GL20: 6.85 | GM20: 6.85 | GN20: 6.85 | GO20: 6.85 | GP20: 6.85 | GQ20: 6.85 | GR20: 6.85 | GS20: 6.85 | GT20: 6.85
B21: -SPESE TELEPASS | C21: =SUM(V21:AG21) -> 253.62 | D21: =SUM(AH21:AS21) -> 128.02 | E21: =SUM(AT21:BE21) -> 294.97 | F21: =SUM(BF21:BQ21) -> 262.76 | G21: =SUM(BR21:CC21) -> 157.86 | H21: =SUM(CD21:CO21) -> 52.25 | I21: =SUM(CP21:DA21) -> 0 | K21: =C21/12 -> 21.135 | L21: =D21/12 -> 10.668333 | M21: =E21/12 -> 24.580833 | N21: =F21/12 -> 21.896667 | O21: =G21/12 -> 13.155 | P21: =H21/12 -> 4.3541667 | Q21: =IFERROR(AVERAGEIF(CE21:CP21,">0"),0) -> 52.25 | U21: 55.13 | X21: 93.43 | AA21: 12.53 | AD21: 75.93 | AG21: 71.73 | AJ21: 35.83 | AM21: 34.83 | AP21: 22.53 | AS21: =33.28+1.55 -> 34.83 | AU21: =31.08+1.55 -> 32.63 | AX21: =95.18+1.55 -> 96.73 | BA21: =66.82+1.55 -> 68.37 | BD21: =95.69+1.55 -> 97.24 | BH21: =47.09+1.55 -> 48.64 | BK21: =49.59+1.55 -> 51.14 | BM21: =111.49+1.55 -> 113.04 | BP21: =48.39+1.55 -> 49.94 | BS21: =50.59+1.55 -> 52.14 | BW21: =85.19+1.55 -> 86.74 | CC21: =17.43+1.55 -> 18.98 | CO21: =50.7+1.55 -> 52.25
B22: -SPESA GAS | C22: =SUM(V22:AG22) -> 0 | D22: =SUM(AH22:AS22) -> 521.58 | E22: =SUM(AT22:BE22) -> 610.8 | F22: =SUM(BF22:BQ22) -> 333.84 | G22: =SUM(BR22:CC22) -> 718.14 | H22: =SUM(CD22:CO22) -> 743.07 | I22: =SUM(CP22:DA22) -> 840.12503 | K22: =C22/12 -> 0 | L22: =D22/12 -> 43.465 | M22: =E22/12 -> 50.9 | N22: =F22/12 -> 27.82 | O22: =G22/12 -> 59.845 | P22: =H22/12 -> 61.9225 | Q22: =I22/12 -> 70.010419 | AI22: 111.86 | AK22: 100.96 | AM22: 66.38 | AO22: 41.39 | AQ22: 37.5 | AS22: 163.49 | AU22: =372.21+0.5 -> 372.71 | AW22: =44.18+18+0.5+0.5 -> 63.18 | AY22: =40.16+0.5 -> 40.66 | BA22: =35.03+0.5 -> 35.53 | BC22: =17.33+0.5 -> 17.83 | BE22: =80.39+0.5 -> 80.89 | BG22: ='ANALISI CONSUMI GAS ENERGIA'!AL17+0.5 -> 48.97 | BH22: ='ANALISI CONSUMI GAS ENERGIA'!AN17+0.5 -> 112.98 | BK22: ='ANALISI CONSUMI GAS ENERGIA'!AP17+0.5 -> 58.88 | BM22: ='ANALISI CONSUMI GAS ENERGIA'!AR17+0.5 -> 39.85 | BO22: ='ANALISI CONSUMI GAS ENERGIA'!AT17+0.5 -> 35 | BQ22: ='ANALISI CONSUMI GAS ENERGIA'!AV17+0.5 -> 38.16 | BS22: ='ANALISI CONSUMI GAS ENERGIA'!AX17+0.5 -> 197.9 | BU22: ='ANALISI CONSUMI GAS ENERGIA'!AZ17+0.5 -> 268.9 | BW22: ='ANALISI CONSUMI GAS ENERGIA'!BB17+0.5 -> 108.26 | BY22: ='ANALISI CONSUMI GAS ENERGIA'!BD17+0.5 -> 49.26 | CA22: ='ANALISI CONSUMI GAS ENERGIA'!BF17+0.5 -> 45.79 | CC22: ='ANALISI CONSUMI GAS ENERGIA'!BH17+0.5 -> 48.03 | CE22: ='ANALISI CONSUMI GAS ENERGIA'!BJ17+0.5 -> 270.53 | CG22: ='ANALISI CONSUMI GAS ENERGIA'!BL17+0.5 -> 228.34 | CI22: ='ANALISI CONSUMI GAS ENERGIA'!BN17+0.5 -> 96.49 | CK22: ='ANALISI CONSUMI GAS ENERGIA'!BP17+0.5 -> 49.78 | CM22: ='ANALISI CONSUMI GAS ENERGIA'!BR17+0.5 -> 47.81 | CO22: ='ANALISI CONSUMI GAS ENERGIA'!BT17+0.5 -> 50.12 | CQ22: ='ANALISI CONSUMI GAS ENERGIA'!BV17+0.5 -> 272.08 | CS22: ='ANALISI CONSUMI GAS ENERGIA'!BX17+0.5 -> 319.82 | CU22: ='ANALISI CONSUMI GAS ENERGIA'!BZ17+0.5 -> 120.97 | CW22: 30.25 | CX22: 21.23 | CY22: 20.29 | DA22: ='ANALISI CONSUMI GAS ENERGIA'!CK17 -> 55.485032 | DC22: 270.53 | DE22: 228.34 | DG22: 96.49 | DI22: 49.78 | DK22: 46.517834 | DM22: 47.187905 | DO22: 270.53 | DQ22: 228.34 | DS22: 96.49 | DU22: 49.78 | DW22: 46.517834 | DY22: 47.187905 | EA22: 270.53 | EC22: 228.34 | EE22: 96.49 | EG22: 49.78 | EI22: 46.517834 | EK22: 47.187905 | EM22: 270.53 | EO22: 228.34 | EQ22: 96.49 | ES22: 49.78 | EU22: 46.517834 | EW22: 47.187905 | EY22: 270.53 | FA22: 228.34 | FC22: 96.49 | FE22: 49.78 | FG22: 46.517834 | FI22: 47.187905 | FK22: 270.53 | FM22: 228.34 | FO22: 96.49 | FQ22: 49.78 | FS22: 46.517834 | FU22: 47.187905 | FW22: 270.53 | FY22: 228.34 | GA22: 96.49 | GC22: 49.78 | GE22: 46.517834 | GG22: 47.187905 | GI22: 270.53 | GK22: 228.34 | GM22: 96.49 | GO22: 49.78 | GQ22: 46.517834 | GS22: 47.187905
B23: -SPESA LUCE | C23: =SUM(V23:AG23) -> 0 | D23: =SUM(AH23:AS23) -> 828.89 | E23: =SUM(AT23:BE23) -> 556.23 | F23: =SUM(BF23:BQ23) -> 573.19 | G23: =SUM(BR23:CC23) -> 754.73 | H23: =SUM(CD23:CO23) -> 807.44 | I23: =SUM(CP23:DA23) -> 885.69108 | K23: =C23/12 -> 0 | L23: =D23/12 -> 69.074167 | M23: =E23/12 -> 46.3525 | N23: =F23/12 -> 47.765833 | O23: =G23/12 -> 62.894167 | P23: =H23/12 -> 67.286667 | Q23: =I23/12 -> 73.80759 | AI23: 272.57 | AK23: 133.32 | AM23: 116.72 | AO23: 111.88 | AQ23: 110.75 | AS23: 83.65 | AU23: ='ANALISI CONSUMI GAS ENERGIA'!Z60 -> 101.33 | AW23: =51.4+0.5 -> 51.9 | AY23: =78.61+0.5+18+0.5 -> 97.61 | BA23: =81.65+0.5+18+0.5 -> 100.65 | BB23: =96.31+0.5+9+0.5 -> 106.31 | BE23: =79.43+18+0.5+0.5 -> 98.43 | BG23: ='ANALISI CONSUMI GAS ENERGIA'!AL60+0.5 -> 80.25 | BI23: =18+0.5+69.65+0.5 -> 88.65 | BJ23: =18+0.5+67.91+0.5 -> 86.91 | BM23: ='ANALISI CONSUMI GAS ENERGIA'!AR60+0.5 -> 89.14 | BN23: ='ANALISI CONSUMI GAS ENERGIA'!AT60+0.5 -> 125.24 | BP23: ='ANALISI CONSUMI GAS ENERGIA'!AV60+0.5 -> 103 | BS23: ='ANALISI CONSUMI GAS ENERGIA'!AX60+0.5 -> 106.64 | BT23: ='ANALISI CONSUMI GAS ENERGIA'!AZ60+0.5 -> 129.6 | BV23: ='ANALISI CONSUMI GAS ENERGIA'!BB60+0.5 -> 127.71 | BY23: ='ANALISI CONSUMI GAS ENERGIA'!BD60+0.5 -> 138.12 | CA23: ='ANALISI CONSUMI GAS ENERGIA'!BF60+0.5 -> 147.4 | CC23: ='ANALISI CONSUMI GAS ENERGIA'!BH60+0.5 -> 105.26 | CE23: ='ANALISI CONSUMI GAS ENERGIA'!BJ60+0.5 -> 108.18 | CG23: ='ANALISI CONSUMI GAS ENERGIA'!BL60+0.5 -> 127.39 | CI23: ='ANALISI CONSUMI GAS ENERGIA'!BN60+0.5 -> 125.2 | CK23: ='ANALISI CONSUMI GAS ENERGIA'!BP60+0.5 -> 146.5 | CM23: ='ANALISI CONSUMI GAS ENERGIA'!BR60+0.5 -> 169.76 | CO23: ='ANALISI CONSUMI GAS ENERGIA'!BT60+0.5 -> 130.41 | CQ23: ='ANALISI CONSUMI GAS ENERGIA'!BV60+0.5 -> 131.96 | CS23: ='ANALISI CONSUMI GAS ENERGIA'!BX60+0.5 -> 138.62 | CU23: ='ANALISI CONSUMI GAS ENERGIA'!BZ60+0.5 -> 134.74 | CV23: 69.45 | CW23: 90.27 | CX23: 92.14 | CY23: 97.72 | DA23: ='ANALISI CONSUMI GAS ENERGIA'!CK60 -> 130.79108 | DC23: 108.18 | DE23: 127.39 | DG23: 125.2 | DI23: 146.5 | DK23: 153.4832 | DM23: 119.65911 | DO23: 108.18 | DQ23: 127.39 | DS23: 125.2 | DU23: 146.5 | DW23: 153.4832 | DY23: 119.65911 | EA23: 108.18 | EC23: 127.39 | EE23: 125.2 | EG23: 146.5 | EI23: 153.4832 | EK23: 119.65911 | EM23: 108.18 | EO23: 127.39 | EQ23: 125.2 | ES23: 146.5 | EU23: 153.4832 | EW23: 119.65911 | EY23: 108.18 | FA23: 127.39 | FC23: 125.2 | FE23: 146.5 | FG23: 153.4832 | FI23: 119.65911 | FK23: 108.18 | FM23: 127.39 | FO23: 125.2 | FQ23: 146.5 | FS23: 153.4832 | FU23: 119.65911 | FW23: 108.18 | FY23: 127.39 | GA23: 125.2 | GC23: 146.5 | GE23: 153.4832 | GG23: 119.65911 | GI23: 108.18 | GK23: 127.39 | GM23: 125.2 | GO23: 146.5 | GQ23: 153.4832 | GS23: 119.65911
B24: - PRELIEVO CONTANTI | C24: =SUM(V24:AG24) -> 0 | D24: =SUM(AH24:AS24) -> 3652 | E24: =SUM(AT24:BE24) -> 1980 | F24: =SUM(BF24:BQ24) -> 220 | G24: =SUM(BR24:CC24) -> 442 | H24: =SUM(CD24:CO24) -> 1030 | I24: =SUM(CP24:DA24) -> 1466 | K24: =C24/12 -> 0 | L24: =D24/12 -> 304.33333 | M24: =E24/12 -> 165 | N24: =F24/12 -> 18.333333 | O24: =G24/12 -> 36.833333 | P24: =H24/12 -> 85.833333 | Q24: =IFERROR(AVERAGEIF(CP24:DA24,">0"),0) -> 209.42857 | AJ24: =500+550+500+550 -> 2100 | AK24: 70 | AM24: =100+70 -> 170 | AN24: =50+50+150+100 -> 350 | AO24: =150+100+100 -> 350 | AP24: =250 -> 250 | AQ24: =100+2 -> 102 | AS24: =50+60+50+100 -> 260 | AU24: =100+70+60+50 -> 280 | AV24: =40+40+40 -> 120 | AW24: =60+70+70+70+40+40 -> 350 | AX24: =60+60 -> 120 | AY24: =70+60 -> 130 | BA24: =60+120 -> 180 | BB24: =250+60 -> 310 | BE24: =100+60+60+70+60+80+60 -> 490 | BF24: =60+40 -> 100 | BN24: 50 | BQ24: 70 | BT24: =90+2 -> 92 | BW24: 70 | BZ24: 70 | CA24: =40 -> 40 | CC24: =100+70 -> 170 | CD24: =70+70+70 -> 210 | CF24: 90 | CH24: 70 | CJ24: 70 | CK24: =70+40 -> 110 | CM24: =100+40 -> 140 | CO24: =150+70+50+70 -> 340 | CR24: =70+2 -> 72 | CS24: 80 | CT24: =100+150+100 -> 350 | CU24: =200+80 -> 280 | CV24: 70 | CW24: =80+70+40 -> 190 | CX24: =150+70+2+200+2 -> 424
B25: - RATE MENSILI VARIE | C25: =SUM(V25:AG25) -> 0 | D25: =SUM(AH25:AS25) -> 638.4 | E25: =SUM(AT25:BE25) -> 91.2 | F25: =SUM(BF25:BQ25) -> 0 | G25: =SUM(BR25:CC25) -> 588.87 | H25: =SUM(CD25:CO25) -> 528.53 | I25: =SUM(CP25:DA25) -> 2021.24 | K25: =C25/12 -> 0 | L25: =D25/12 -> 53.2 | M25: =E25/12 -> 7.6 | N25: =F25/12 -> 0 | O25: =G25/12 -> 49.0725 | P25: =H25/12 -> 44.044167 | Q25: =I25/12 -> 168.43667 | AM25: 91.2 | AN25: 91.2 | AO25: 91.2 | AP25: 91.2 | AQ25: 91.2 | AR25: 91.2 | AS25: 91.2 | AT25: 91.2 | BR25: =63.45+2.5 -> 65.95 | BS25: =63.45+2.5 -> 65.95 | BT25: =63.45+2.5 -> 65.95 | BU25: =63.45+2.5 -> 65.95 | BV25: =63.45+2.5 -> 65.95 | BW25: =63.44+2.5 -> 65.94 | CB25: =95.34 -> 95.34 | CC25: =(95.34+2.5) -> 97.84 | CD25: =214.61+2.5 -> 217.11 | CE25: =(119.26+2.5) -> 121.76 | CF25: 121.77 | CO25: =65.39+2.5 -> 67.89 | CP25: =65.4+120.76+2.5 -> 188.66 | CQ25: =65.4+120.77+2.5 -> 188.67 | CR25: =120.77+2.5 -> 123.27 | CS25: =120.77+2.5+249.23 -> 372.5 | CT25: =120.77+2.5+249.23 -> 372.5 | CU25: =370.04+2.5 -> 372.54 | CW25: =37.6+2.5 -> 40.1 | CX25: =37.6+2.5+50.65 -> 90.75 | CY25: =37.6+2.5+50.65 -> 90.75 | CZ25: =37.6+2.5+50.65 -> 90.75 | DA25: =37.6+2.5+50.65 -> 90.75 | DB25: =2.5+50.65 -> 53.15
B26: - SPESE GENERICHE | C26: =SUM(V26:AG26) -> 9181.81 | D26: =SUM(AH26:AS26) -> 7707.81 | E26: =SUM(AT26:BE26) -> 2988.77 | F26: =SUM(BF26:BQ26) -> 1673.08 | G26: =SUM(BR26:CC26) -> 2606.85 | H26: =SUM(CD26:CO26) -> 2155.26 | I26: =SUM(CP26:DA26) -> 6120.49 | K26: =C26/12 -> 765.15083 | L26: =D26/12 -> 642.3175 | M26: =E26/12 -> 249.06417 | N26: =F26/12 -> 139.42333 | O26: =G26/12 -> 217.2375 | P26: =H26/12 -> 179.605 | Q26: =IFERROR(AVERAGEIF(CP26:DA26,">0"),0) -> 765.06125 | S26: ='Riepilogo Mensile BANCOMAT'!K2 -> 0 | T26: ='Riepilogo Mensile BANCOMAT'!L2 -> 25 | U26: ='Riepilogo Mensile BANCOMAT'!M2 -> 687.75 | V26: ='Riepilogo Mensile BANCOMAT'!B3 -> 261.89 | W26: ='Riepilogo Mensile BANCOMAT'!C3 -> 512 | X26: ='Riepilogo Mensile BANCOMAT'!D3 -> 148.8 | Y26: ='Riepilogo Mensile BANCOMAT'!E3 -> 40 | Z26: ='Riepilogo Mensile BANCOMAT'!F3 -> 142 | AA26: ='Riepilogo Mensile BANCOMAT'!G3 -> 352.5 | AB26: ='Riepilogo Mensile BANCOMAT'!H3 -> 190 | AC26: ='Riepilogo Mensile BANCOMAT'!I3 -> 528.4 | ... AG26: ='Riepilogo Mensile BANCOMAT'!M3 -> 5424.98 | AH26: ='Riepilogo Mensile BANCOMAT'!B4 -> 40 | AI26: ='Riepilogo Mensile BANCOMAT'!C4 -> 3076.73 | AJ26: ='Riepilogo Mensile BANCOMAT'!D4 -> 1265.5 | AK26: ='Riepilogo Mensile BANCOMAT'!E4 -> 92.3 | AL26: ='Riepilogo Mensile BANCOMAT'!F4 -> 65.04 | AM26: ='Riepilogo Mensile BANCOMAT'!G4 -> 0 | AN26: ='Riepilogo Mensile BANCOMAT'!H4 -> 549.81 | AO26: ='Riepilogo Mensile BANCOMAT'!I4 -> 1249.1 | ... AS26: ='Riepilogo Mensile BANCOMAT'!M4 -> 827.33 | AT26: ='Riepilogo Mensile BANCOMAT'!B5 -> 1421.01 | AU26: ='Riepilogo Mensile BANCOMAT'!C5 -> 90.41 | AV26: ='Riepilogo Mensile BANCOMAT'!D5 -> 0 | AW26: ='Riepilogo Mensile BANCOMAT'!E5 -> 497.34 | AX26: ='Riepilogo Mensile BANCOMAT'!F5 -> 104.83 | AY26: ='Riepilogo Mensile BANCOMAT'!G5 -> 2 | AZ26: ='Riepilogo Mensile BANCOMAT'!H5 -> 120.5 | BA26: ='Riepilogo Mensile BANCOMAT'!I5 -> 363.4 | ... BE26: ='Riepilogo Mensile BANCOMAT'!M5 -> 256.65 | BF26: ='Riepilogo Mensile BANCOMAT'!B6 -> 356.29 | BG26: ='Riepilogo Mensile BANCOMAT'!C6 -> 0 | BH26: ='Riepilogo Mensile BANCOMAT'!D6 -> 150.5 | BI26: ='Riepilogo Mensile BANCOMAT'!E6 -> 16.8 | BJ26: ='Riepilogo Mensile BANCOMAT'!F6 -> 250 | BK26: ='Riepilogo Mensile BANCOMAT'!G6 -> 0 | BL26: ='Riepilogo Mensile BANCOMAT'!H6 -> 0 | BM26: ='Riepilogo Mensile BANCOMAT'!I6 -> 620.5 | ... BQ26: ='Riepilogo Mensile BANCOMAT'!M6 -> 125.49 | BR26: ='Riepilogo Mensile BANCOMAT'!B7 -> 373.72 | BS26: ='Riepilogo Mensile BANCOMAT'!C7 -> 150.5 | BT26: ='Riepilogo Mensile BANCOMAT'!D7 -> 207.78 | BU26: ='Riepilogo Mensile BANCOMAT'!E7 -> -68 | BV26: ='Riepilogo Mensile BANCOMAT'!F7 -> 79 | BW26: ='Riepilogo Mensile BANCOMAT'!G7 -> 10.2 | BX26: ='Riepilogo Mensile BANCOMAT'!H7 -> 15.04 | BY26: ='Riepilogo Mensile BANCOMAT'!I7 -> 917.6 | ... CC26: ='Riepilogo Mensile BANCOMAT'!M7 -> 604.64 | CD26: ='Riepilogo Mensile BANCOMAT'!B8 -> 364.41 | CE26: ='Riepilogo Mensile BANCOMAT'!C8 -> 26.34 | CF26: ='Riepilogo Mensile BANCOMAT'!D8 -> 637.25 | CG26: ='Riepilogo Mensile BANCOMAT'!E8 -> 532.48 | CH26: ='Riepilogo Mensile BANCOMAT'!F8 -> 4.75 | CI26: ='Riepilogo Mensile BANCOMAT'!G8 -> 0 | CJ26: ='Riepilogo Mensile BANCOMAT'!H8 -> 0 | CK26: ='Riepilogo Mensile BANCOMAT'!I8 -> 48.65 | ... CO26: ='Riepilogo Mensile BANCOMAT'!M8 -> 404.4 | CP26: ='Riepilogo Mensile BANCOMAT'!B9 -> 291.84 | CQ26: ='Riepilogo Mensile BANCOMAT'!C9 -> 0 | CR26: ='Riepilogo Mensile BANCOMAT'!D9 -> 72.6 | CS26: ='Riepilogo Mensile BANCOMAT'!E9 -> 1434.78 | CT26: ='Riepilogo Mensile BANCOMAT'!F9 -> 201.23 | CU26: ='Riepilogo Mensile BANCOMAT'!G9 -> 662.62 | CV26: ='Riepilogo Mensile BANCOMAT'!H9 -> 230.94 | CW26: ='Riepilogo Mensile BANCOMAT'!I9 -> 2423.64 | ... DA26: ='Riepilogo Mensile BANCOMAT'!M9 -> 0 | DB26: ='Riepilogo Mensile BANCOMAT'!B10 -> 0 | DC26: ='Riepilogo Mensile BANCOMAT'!C10 -> 0 | DD26: ='Riepilogo Mensile BANCOMAT'!D10 -> 0 | DE26: ='Riepilogo Mensile BANCOMAT'!E10 -> 0 | DF26: ='Riepilogo Mensile BANCOMAT'!F10 -> 0 | DG26: ='Riepilogo Mensile BANCOMAT'!G10 -> 0 | DH26: ='Riepilogo Mensile BANCOMAT'!H10 -> 0 | DI26: ='Riepilogo Mensile BANCOMAT'!I10 -> 0 | ... DM26: ='Riepilogo Mensile BANCOMAT'!M10 -> 0 | DN26: ='Riepilogo Mensile BANCOMAT'!B11 -> 0 | DO26: ='Riepilogo Mensile BANCOMAT'!C11 -> 0 | DP26: ='Riepilogo Mensile BANCOMAT'!D11 -> 0 | DQ26: ='Riepilogo Mensile BANCOMAT'!E11 -> 0 | DR26: ='Riepilogo Mensile BANCOMAT'!F11 -> 0 | DS26: ='Riepilogo Mensile BANCOMAT'!G11 -> 0 | DT26: ='Riepilogo Mensile BANCOMAT'!H11 -> 0 | DU26: ='Riepilogo Mensile BANCOMAT'!I11 -> 0 | ... DY26: ='Riepilogo Mensile BANCOMAT'!M11 -> 0 | DZ26: ='Riepilogo Mensile BANCOMAT'!B12 -> 0 | EA26: ='Riepilogo Mensile BANCOMAT'!C12 -> 0 | EB26: ='Riepilogo Mensile BANCOMAT'!D12 -> 0 | EC26: ='Riepilogo Mensile BANCOMAT'!E12 -> 0 | ED26: ='Riepilogo Mensile BANCOMAT'!F12 -> 0 | EE26: ='Riepilogo Mensile BANCOMAT'!G12 -> 0 | EF26: ='Riepilogo Mensile BANCOMAT'!H12 -> 0 | EG26: ='Riepilogo Mensile BANCOMAT'!I12 -> 0 | ... EK26: ='Riepilogo Mensile BANCOMAT'!M12 -> 0 | EL26: ='Riepilogo Mensile BANCOMAT'!B13 -> 0 | EM26: ='Riepilogo Mensile BANCOMAT'!C13 -> 0 | EN26: ='Riepilogo Mensile BANCOMAT'!D13 -> 0 | EO26: ='Riepilogo Mensile BANCOMAT'!E13 -> 0 | EP26: ='Riepilogo Mensile BANCOMAT'!F13 -> 0 | EQ26: ='Riepilogo Mensile BANCOMAT'!G13 -> 0 | ER26: ='Riepilogo Mensile BANCOMAT'!H13 -> 0 | ES26: ='Riepilogo Mensile BANCOMAT'!I13 -> 0 | ... EW26: ='Riepilogo Mensile BANCOMAT'!M13 -> 0 | EX26: ='Riepilogo Mensile BANCOMAT'!B14 -> 0 | EY26: ='Riepilogo Mensile BANCOMAT'!C14 -> 0 | EZ26: ='Riepilogo Mensile BANCOMAT'!D14 -> 0 | FA26: ='Riepilogo Mensile BANCOMAT'!E14 -> 0 | FB26: ='Riepilogo Mensile BANCOMAT'!F14 -> 0 | FC26: ='Riepilogo Mensile BANCOMAT'!G14 -> 0 | FD26: ='Riepilogo Mensile BANCOMAT'!H14 -> 0 | FE26: ='Riepilogo Mensile BANCOMAT'!I14 -> 0 | ... FI26: ='Riepilogo Mensile BANCOMAT'!M14 -> 0 | FJ26: ='Riepilogo Mensile BANCOMAT'!B15 -> 0 | FK26: ='Riepilogo Mensile BANCOMAT'!C15 -> 0 | FL26: ='Riepilogo Mensile BANCOMAT'!D15 -> 0 | FM26: ='Riepilogo Mensile BANCOMAT'!E15 -> 0 | FN26: ='Riepilogo Mensile BANCOMAT'!F15 -> 0 | FO26: ='Riepilogo Mensile BANCOMAT'!G15 -> 0 | FP26: ='Riepilogo Mensile BANCOMAT'!H15 -> 0 | FQ26: ='Riepilogo Mensile BANCOMAT'!I15 -> 0 | ... FU26: ='Riepilogo Mensile BANCOMAT'!M15 -> 0 | FV26: ='Riepilogo Mensile BANCOMAT'!B16 -> 0 | FW26: ='Riepilogo Mensile BANCOMAT'!C16 -> 0 | FX26: ='Riepilogo Mensile BANCOMAT'!D16 -> 0 | FY26: ='Riepilogo Mensile BANCOMAT'!E16 -> 0 | FZ26: ='Riepilogo Mensile BANCOMAT'!F16 -> 0 | GA26: ='Riepilogo Mensile BANCOMAT'!G16 -> 0 | GB26: ='Riepilogo Mensile BANCOMAT'!H16 -> 0 | GC26: ='Riepilogo Mensile BANCOMAT'!I16 -> 0 | ... GG26: ='Riepilogo Mensile BANCOMAT'!M16 -> 0 | GH26: ='Riepilogo Mensile BANCOMAT'!B17 -> 0 | GI26: ='Riepilogo Mensile BANCOMAT'!C17 -> 0 | GJ26: ='Riepilogo Mensile BANCOMAT'!D17 -> 0 | GK26: ='Riepilogo Mensile BANCOMAT'!E17 -> 0 | GL26: ='Riepilogo Mensile BANCOMAT'!F17 -> 0 | GM26: ='Riepilogo Mensile BANCOMAT'!G17 -> 0 | GN26: ='Riepilogo Mensile BANCOMAT'!H17 -> 0 | GO26: ='Riepilogo Mensile BANCOMAT'!I17 -> 0 | ... GS26: ='Riepilogo Mensile BANCOMAT'!M17 -> 0 | GT26: ='Riepilogo Mensile BANCOMAT'!B18 -> 0
B27: TOTALE SPESE CONTO | C27: =SUM(C15:C26) -> 30664.82 | D27: =SUM(D15:D26) -> 25975.44 | E27: =SUM(E15:E26) -> 53374.24 | F27: =SUM(F15:F26) -> 17390.07 | G27: =SUM(G15:G26) -> 18840.65 | H27: =SUM(H15:H26) -> 17417.75 | I27: =SUM(CP27:DA27) -> 24640.746 | K27: =C27/12 -> 2555.4017 | L27: =D27/12 -> 2164.62 | M27: =E27/12 -> 4447.8533 | N27: =F27/12 -> 1449.1725 | O27: =G27/12 -> 1570.0542 | P27: =H27/12 -> 1451.4792 | Q27: =IFERROR(AVERAGEIF(CP27:DA27,">0"),0) -> 2053.3955 | S27: =SUM(S15:S26) -> 776.93 | T27: =SUM(T15:T26) -> 801.93 | U27: =SUM(U15:U26) -> 1519.81 | V27: =SUM(V15:V26) -> 1038.82 | W27: =SUM(W15:W26) -> 1468.93 | X27: =SUM(X15:X26) -> 1019.16 | Y27: =SUM(Y15:Y26) -> 816.93 | Z27: =SUM(Z15:Z26) -> 1099.02 | ... AH27: =SUM(AH15:AH26) -> 911.23 | AI27: =SUM(AI15:AI26)-AI22-AI23 -> 3879.73 | AJ27: =SUM(AJ15:AJ26) -> 4162.39 | AK27: =SUM(AK15:AK26)-AK22-AK23 -> 1021.68 | AL27: =SUM(AL15:AL26) -> 924.51 | AM27: =SUM(AM15:AM26)-AM22-AM23 -> 1200.88 | AN27: =SUM(AN15:AN26) -> 1845.86 | AO27: =SUM(AO15:AO26)-AO22-AO23 -> 2947.28 | AP27: =SUM(AP15:AP26) -> 1800.71 | AQ27: =SUM(AQ15:AQ26)-AQ22-AQ23 -> 1783.08 | AR27: =SUM(AR15:AR26) -> 1577.28 | AS27: =SUM(AS15:AS26) -> 2817.48 | AT27: =SUM(AT15:AT26) -> 2768.29 | AU27: =SUM(AU15:AU26) -> 15847.79 | AV27: =SUM(AV15:AV26) -> 967.73 | AW27: =SUM(AW15:AW26) -> 1910.15 | AX27: =SUM(AX15:AX26) -> 1472.38 | AY27: =SUM(AY15:AY26) -> 1248.87 | ... GT27: =SUM(GT15:GT26) -> 746.85
B28: +ENTRATE STRAORDINARIE | C28: =SUM(V28:AG28) -> 1801.12 | D28: =SUM(AH28:AS28) -> 11202 | E28: =SUM(AT28:BE28) -> 33045.29 | F28: =SUM(BF28:BQ28) -> 1061.75 | G28: =SUM(BR28:CC28) -> 2770.49 | H28: =SUM(CD28:CO28) -> 1874.34 | I28: =SUM(CP28:DA28) -> 4205.83 | K28: =C28/12 -> 150.09333 | L28: =D28/12 -> 933.5 | M28: =E28/12 -> 2753.7742 | N28: =F28/12 -> 88.479167 | O28: =G28/12 -> 230.87417 | P28: =H28/12 -> 156.195 | Q28: =IFERROR(SUM(CP28:DA28)/12,0) -> 350.48583 | U28: =200+0.87 -> 200.87 | W28: =180 -> 180 | Z28: 180 | AB28: 220 | AC28: 180 | AD28: 420 | AE28: 210 | AF28: =290+60 -> 350 | AG28: =60+1.12 -> 61.12 | AH28: 60 | AI28: =2000+2650 -> 4650 | AJ28: =630 -> 630 | AM28: =250 -> 250 | AN28: =200+70+5000+200 -> 5470 | AR28: =42+100 -> 142 | AT28: =0.08+13800 -> 13800.08 | AV28: 475.2 | AW28: 18400 | AZ28: =200 -> 200 | BA28: =70 -> 70 | BB28: =100+0.01 -> 100.01 | BF28: 0.12 | BH28: 150 | BJ28: =250 -> 250 | BL28: 380 | BM28: 281.63 | BR28: 0.03 | BV28: 125 | BY28: =255.46 -> 255.46 | BZ28: =100 -> 100 | CA28: =700+200+69+700 -> 1669 | CB28: =77+300 -> 377 | CC28: =(120+62+62) -> 244 | CD28: =0.06+65 -> 65.06 | CF28: =165+85 -> 250 | CG28: =30+30+40+137+77 -> 314 | CK28: =480.28 -> 480.28 | CL28: =87+76+62 -> 225 | CM28: =230+100 -> 330 | CN28: 210 | CP28: =0.11+150 -> 150.11 | CQ28: =136 -> 136 | CS28: =130+440 -> 570 | CU28: =230+150 -> 380 | CV28: 69.45 | CW28: =90.27+1266+418.09+650+30.25 -> 2454.61 | CX28: =21.23+92.14+150+162 -> 425.37 | CY28: =20.29 -> 20.29
B29: +DETRAZIONI IRPEF | C29: =SUM(V29:AG29) -> 0 | D29: =SUM(AH29:AS29) -> 0 | E29: =SUM(AT29:BE29) -> 804 | F29: =SUM(BF29:BQ29) -> 854 | G29: =SUM(BR29:CC29) -> 763 | H29: =SUM(CD29:CO29) -> 590 | I29: =SUM(CP29:DA29) -> 0 | K29: =C29/12 -> 0 | L29: =D29/12 -> 0 | M29: =E29/12 -> 67 | N29: =F29/12 -> 71.166667 | O29: =G29/12 -> 63.583333 | P29: =H29/12 -> 49.166667 | Q29: =IFERROR(SUM(CP29:DA29)/12,0) -> 0 | BA29: 804 | BN29: 854 | BY29: 763 | CK29: 590
B30: TOTALE ENTRATE EXTRA | C30: =SUM(V30:AG30) -> 7592.12 | D30: =SUM(AH30:AS30) -> 14492 | E30: =SUM(AT30:BE30) -> 37720.29 | F30: =SUM(BF30:BQ30) -> 4247.75 | G30: =SUM(BR30:CC30) -> 9773.49 | H30: =SUM(CD30:CO30) -> 8401.34 | I30: =SUM(CP30:DA30) -> 54325.88 | K30: =C30/12 -> 632.67667 | L30: =D30/12 -> 1207.6667 | M30: =E30/12 -> 3143.3575 | N30: =F30/12 -> 353.97917 | O30: =G30/12 -> 814.4575 | P30: =H30/12 -> 700.11167 | Q30: =IFERROR(SUM(CP30:DA30)/12,0) -> 4527.1567 | S30: =S28+S29+S12 -> 0 | T30: =T28+T29+T12 -> 0 | U30: =U28+U29+U12 -> 3725.87 | V30: =V28+V29+V12 -> 0 | W30: =W28+W29+W12 -> 180 | X30: =X28+X29+X12 -> 0 | Y30: =Y28+Y29+Y12 -> 0 | Z30: =Z28+Z29+Z12 -> 180 | ... GT30: =GT28+GT29+GT12 -> 0
B31: - ADDEBITO CARTA DI CREDITO | C31: =SUM(V31:AG31) -> 12941.27 | D31: =SUM(AH31:AS31) -> 13633.79 | E31: =SUM(AT31:BE31) -> 12785.23 | F31: =SUM(BF31:BQ31) -> 15000.66 | G31: =SUM(BR31:CC31) -> 15763.13 | H31: =SUM(CD31:CO31) -> 18091.008 | I31: =SUM(CP31:DA31) -> 20013.164 | K31: =C31/12 -> 1078.4392 | L31: =D31/12 -> 1136.1492 | M31: =E31/12 -> 1065.4358 | N31: =F31/12 -> 1250.055 | O31: =G31/12 -> 1313.5942 | P31: =H31/12 -> 1507.584 | Q31: =IFERROR(AVERAGEIF(CE31:CP31,">0"),0) -> 1565.674 | S31: =IF(S64="",$C$64,S64) -> 925 | T31: =IF(T8=0,Valutazioni!$C$3,T64) -> 1075.5 | U31: =IF(U8=0,Valutazioni!$C$3,U64) -> 1120.38 | V31: =IF(V8=0,Valutazioni!$C$3,V64) -> 1713.29 | W31: =IF(W8=0,Valutazioni!$C$3,W64) -> 874.86 | X31: =IF(X8=0,Valutazioni!$C$3,X64) -> 1181.77 | Y31: =IF(Y8=0,Valutazioni!$C$3,Y64) -> 984.2 | Z31: =IF(Z8=0,Valutazioni!$C$3,Z64) -> 694.98 | AA31: =IF(AA8=0,Valutazioni!$C$3,AA64) -> 850.93 | ... CY31: =IF(CY8=0,Valutazioni!$C$3,CY64) -> 2230.93 | CZ31: =IF(CZ8=0,$B$67*(1+$B$68),CZ64+Valutazioni!$I$3) -> 1100 | DA31: =IF(DA8=0,$B$67*(1+$B$68),DA64+Valutazioni!$I$3) -> 1100 | DB31: =IF(DB8=0,$B$67*(1+$B$68),DB64+Valutazioni!$I$3) -> 1100 | DC31: =IF(DC8=0,$B$67*(1+$B$68),DC64+Valutazioni!$I$3) -> 1100 | DD31: =IF(DD8=0,$B$67*(1+$B$68),DD64+Valutazioni!$I$3) -> 1100 | DE31: =IF(DE8=0,$B$67*(1+$B$68),DE64+Valutazioni!$I$3) -> 1100 | DF31: =IF(DF8=0,$B$67*(1+$B$68),DF64+Valutazioni!$I$3) -> 1100 | DG31: =IF(DG8=0,$B$67*(1+$B$68),DG64+Valutazioni!$I$3) -> 1100 | ... GT31: =IF(GT8=0,$B$67*(1+$B$68),GT64+Valutazioni!$I$3) -> 1100
B32: SALDO CONTO | C32: =C11-C27+C30-C31 -> -9327.97 | D32: =D11-D27+D30-D31 -> 1510.77 | E32: =E11-E27+E30-E31 -> -955.18 | F32: =F11-F27+F30-F31 -> -668.98 | G32: =G11-G27+G30-G31 -> 5272.71 | H32: =H11-H27+H30-H31 -> 3127.582 | I32: =I11-I27+I30-I31 -> 42543.97 | K32: =C32/12 -> -777.33083 | L32: =D32/12 -> 125.8975 | M32: =E32/12 -> -79.598333 | N32: =F32/12 -> -55.748333 | O32: =G32/12 -> 439.3925 | P32: =H32/12 -> 260.63183 | Q32: =I32/12 -> 3545.3308 | S32: =S14-(S27+IF(S31>0,S31,Valutazioni!$C$3)-S28) -> 7851.23 | T32: =T14-(T27+IF(T31>0,T31,Valutazioni!$C$3)-T28) -> 8195.8 | U32: =U14-(U27+IF(U31>0,U31,Valutazioni!$C$3)-U30) -> 11552.48 | V32: =V14-(V27+IF(V31>0,V31,Valutazioni!$C$3)-V30) -> 11541.37 | W32: =W14-(W27+IF(W31>0,W31,Valutazioni!$C$3)-W30) -> 11543.58 | X32: =X14-(X27+IF(X31>0,X31,Valutazioni!$C$3)-X30) -> 11517.65 | Y32: =Y14-(Y27+IF(Y31>0,Y31,Valutazioni!$C$3)-Y30) -> 11874.52 | Z32: =Z14-(Z27+IF(Z31>0,Z31,Valutazioni!$C$3)-Z30) -> 12417.52 | AA32: =AA14-(AA27+IF(AA31>0,AA31,Valutazioni!$C$3)-AA30) -> 12636.56 | AB32: =AB14-(AB27+IF(AB31>0,AB31,Valutazioni!$C$3)-AB30) -> 13224.53 | ... GT32: =GT14-(GT27+IF(GT31>0,GT31,Valutazioni!$C$3)-GT30) -> 123190.3
B33: MARGINE PERCENTUALE % | C33: =C32/(C11+C28) -> -0.32744518 | D33: =D32/(D11+D28) -> 0.039935765 | E33: =E32/(E11+E28) -> -0.015780459 | F33: =F32/(F11+F28) -> -0.023443575 | G33: =G32/(G11+G28) -> 0.16039398 | H33: =H32/(H11+H28) -> 0.09740412 | I33: =I32/(I11+I28) -> 1.1474234 | K33: =K32/(K11+K28) -> -0.32744518 | L33: =L32/(L11+L28) -> 0.039935765 | M33: =M32/(M11+M28) -> -0.015780459 | N33: =N32/(N11+N28) -> -0.023443575 | O33: =O32/(O11+O28) -> 0.16039398 | P33: =P32/(P11+P28) -> 0.09740412 | Q33: =Q32/(Q11+Q28) -> 1.1474234 | T33: =(T32-S32)/S32 -> 0.043887391 | U33: =(U32-T32)/T32 -> 0.40956099 | V33: =(V32-U32)/U32 -> -0.00096169827 | W33: =(W32-V32)/V32 -> 0.00019148507 | X33: =(X32-W32)/W32 -> -0.0022462702 | Y33: =(Y32-X32)/X32 -> 0.030984619 | Z33: =(Z32-Y32)/Y32 -> 0.045728164 | AA33: =(AA32-Z32)/Z32 -> 0.017639593 | ... GT33: =(GT32-GS32)/GS32 -> 0.0064636888
S34: =S9 -> 43739 | T34: =T9 -> 43770 | U34: =U9 -> 43800 | V34: =V9 -> 43831 | W34: =W9 -> 43862 | X34: =X9 -> 43891 | Y34: =Y9 -> 43922 | Z34: =Z9 -> 43952 | ... EQ34: =EQ9 -> 47635
B35: RIMANENZA FINALE | C35: =AG32 -> 2224.51 | D35: =AS32 -> 4838.61 | E35: =BE32 -> 3883.43 | F35: =BQ32 -> 3214.45 | G35: =CC32 -> 8487.16 | H35: =CO32 -> 11614.742 | I35: =DA32 -> 54158.712 | K35: =AVERAGE(V32:AG32) -> 10592.124 | L35: =AVERAGE(AH32:AS32) -> 2915.8117 | M35: =AVERAGE(AT32:BE32) -> 11040.905 | N35: =AVERAGE(BF32:BQ32) -> 2594.7667 | O35: =AVERAGE(BR32:CC32) -> 5674.675 | P35: =AVERAGE(CD32:CO32) -> 10543.306 | Q35: =AVERAGE(CP32:DA32) -> 36557.754
S38: =IF($B$2=S39,TRUE,FALSE) -> FALSE | T38: =IF($B$2=T39,TRUE,FALSE) -> FALSE | U38: =IF($B$2=U39,TRUE,FALSE) -> FALSE | V38: =IF($B$2=V39,TRUE,FALSE) -> FALSE | W38: =IF($B$2=W39,TRUE,FALSE) -> FALSE | X38: =IF($B$2=X39,TRUE,FALSE) -> FALSE | Y38: =IF($B$2=Y39,TRUE,FALSE) -> FALSE | Z38: =IF($B$2=Z39,TRUE,FALSE) -> FALSE | ... GT38: =IF($B$2=GT39,TRUE,FALSE) -> FALSE
B39: SITUAZIONE CARTA DI CREDITO | C39: 2020 | D39: 2021 | E39: 2022 | F39: 2023 | G39: 2024 | H39: 2025 | I39: 2026 | K39: 2020 | L39: 2021 | M39: 2022 | N39: 2023 | O39: 2024 | P39: 2025 | Q39: 2026 | S39: 43718 | T39: 43748 | U39: 43779 | V39: 43809 | W39: 43840 | X39: 43871 | Y39: 43900 | Z39: 43931 | AA39: 43961 | AB39: 43992 | AC39: 44022 | AD39: 44053 | AE39: 44084 | AF39: 44114 | AG39: 44145 | AH39: 44175 | AI39: 44206 | AJ39: 44237 | AK39: 44265 | AL39: 44296 | AM39: 44326 | AN39: 44357 | AO39: 44378 | AP39: 44409 | AQ39: 44440 | AR39: 44470 | AS39: 44501 | AT39: 44531 | AU39: 44562 | AV39: 44593 | AW39: 44621 | AX39: 44652 | AY39: 44682 | AZ39: 44713 | BA39: 44743 | BB39: 44774 | BC39: 44805 | BD39: 44835 | BE39: 44866 | BF39: 44896 | BG39: 44927 | BH39: 44958 | BI39: 44986 | BJ39: 45017 | BK39: 45047 | BL39: 45078 | BM39: 45108 | BN39: 45139 | BO39: 45170 | BP39: 45200 | BQ39: 45231 | BR39: 45261 | BS39: 45292 | BT39: 45323 | BU39: 45352 | BV39: 45383 | BW39: 45413 | BX39: 45444 | BY39: 45474 | BZ39: 45505 | CA39: 45536 | CB39: 45566 | CC39: 45597 | CD39: 45627 | CE39: 45658 | CF39: 45689 | CG39: 45717 | CH39: 45748 | CI39: 45778 | CJ39: 45809 | CK39: 45839 | CL39: 45870 | CM39: 45901 | CN39: 45931 | CO39: 45962 | CP39: 45992 | CQ39: 46023 | CR39: 46054 | CS39: 46082 | CT39: 46113 | CU39: 46143 | CV39: 46174 | CW39: 46204 | CX39: 46235 | CY39: 46266 | CZ39: 46296 | DA39: 46327 | DB39: 46357 | DC39: 46388 | DD39: 46419 | DE39: 46447 | DF39: 46478 | DG39: 46508 | DH39: 46539 | DI39: 46569 | DJ39: 46600 | DK39: 46631 | DL39: 46661 | DM39: 46692 | DN39: 46722 | DO39: 46753 | DP39: 46784 | DQ39: 46813 | DR39: 46844 | DS39: 46874 | DT39: 46905 | DU39: 46935 | DV39: 46966 | DW39: 46997 | DX39: 47027 | DY39: 47058 | DZ39: 47088 | EA39: 47119 | EB39: 47150 | EC39: 47178 | ED39: 47209 | EE39: 47239 | EF39: 47270 | EG39: 47300 | EH39: 47331 | EI39: 47362 | EJ39: 47392 | EK39: 47423 | EL39: 47453 | EM39: 47484 | EN39: 47515 | EO39: 47543 | EP39: 47574 | EQ39: 47604 | ER39: 47635 | ES39: 47665 | ET39: 47696 | EU39: 47727 | EV39: 47757 | EW39: 47788 | EX39: 47818 | EY39: 47849 | EZ39: 47880 | FA39: 47908 | FB39: 47939 | FC39: 47969 | FD39: 48000 | FE39: 48030 | FF39: 48061 | FG39: 48092 | FH39: 48122 | FI39: 48153 | FJ39: 48183 | FK39: 48214 | FL39: 48245 | FM39: 48274 | FN39: 48305 | FO39: 48335 | FP39: 48366 | FQ39: 48396 | FR39: 48427 | FS39: 48458 | FT39: 48488 | FU39: 48519 | FV39: 48549 | FW39: 48580 | FX39: 48611 | FY39: 48639 | FZ39: 48670 | GA39: 48700 | GB39: 48731 | GC39: 48761 | GD39: 48792 | GE39: 48823 | GF39: 48853 | GG39: 48884 | GH39: 48914 | GI39: 48945 | GJ39: 48976 | GK39: 49004 | GL39: 49035 | GM39: 49065 | GN39: 49096 | GO39: 49126 | GP39: 49157 | GQ39: 49188 | GR39: 49218 | GS39: 49249 | GT39: 49279
B40: SPESE FISSE | K40: MEDIA ANNUA CARTA
B41: - MICROSOFT OFFICE | C41: =SUM(V41:AG41) -> 83 | D41: =SUM(AH41:AS41) -> 69 | E41: =SUM(AT41:BE41) -> 59 | F41: =SUM(BF41:BQ41) -> 43.99 | G41: =SUM(BR41:CC41) -> 47.99 | H41: =SUM(CD41:CO41) -> 46.99 | I41: =SUM(CP41:DA41) -> 73.1 | K41: =C41/12 -> 6.9166667 | L41: =D41/12 -> 5.75 | M41: =E41/12 -> 4.9166667 | N41: =F41/12 -> 3.6658333 | O41: =G41/12 -> 3.9991667 | P41: =H41/12 -> 3.9158333 | Q41: =I41/12 -> 6.0916667 | S41: 7 | T41: 7 | U41: 7 | V41: 7 | W41: 7 | X41: 69 | AJ41: 69 | AV41: 19.67 | AW41: 19.67 | AX41: 19.66 | BJ41: 43.99 | BT41: 16 | BU41: 16 | BV41: 15.99 | CH41: 46.99 | CT41: 24.37 | CU41: 24.37 | CV41: =24.36 -> 24.36
B42: - DISNEY PLUS | C42: =SUM(V42:AG42) -> 48.93 | D42: =SUM(AH42:AS42) -> 27.96 | E42: =SUM(AT42:BE42) -> 0 | F42: =SUM(BF42:BQ42) -> 0 | G42: =SUM(BR42:CC42) -> 0 | H42: =SUM(CD42:CO42) -> 8 | I42: =SUM(CP42:DA42) -> 56 | K42: =C42/12 -> 4.0775 | L42: =D42/12 -> 2.33 | M42: =E42/12 -> 0 | N42: =F42/12 -> 0 | O42: =G42/12 -> 0 | P42: =H42/12 -> 0.66666667 | Q42: =I42/12 -> 4.6666667 | Z42: 6.99 | AA42: 6.99 | AC42: 6.99 | AD42: 6.99 | AE42: 6.99 | AF42: 6.99 | AG42: 6.99 | AH42: 6.99 | AI42: 6.99 | AJ42: 6.99 | AK42: 6.99 | CO42: 8 | CP42: 8 | CQ42: 8 | CR42: 8 | CS42: 8 | CT42: 8 | CZ42: 8 | DA42: 8 | DB42: 8 | DC42: 8 | DD42: 8 | DE42: 8 | DF42: 8 | DG42: 8 | DH42: 8 | DI42: 8 | DJ42: 8 | DK42: 8 | DL42: 8 | DM42: 8 | DN42: 8 | DO42: 8 | DP42: 8 | DQ42: 8 | DR42: 8 | DS42: 8 | DT42: 8 | DU42: 8 | DV42: 8 | DW42: 8 | DX42: 8 | DY42: 8 | DZ42: 8 | EA42: 8 | EB42: 8 | EC42: 8 | ED42: 8 | EE42: 8 | EF42: 8 | EG42: 8 | EH42: 8 | EI42: 8 | EJ42: 8 | EK42: 8 | EL42: 8 | EM42: 8 | EN42: 8 | EO42: 8 | EP42: 8 | EQ42: 8 | ER42: 8 | ES42: 8 | ET42: 8 | EU42: 8 | EV42: 8 | EW42: 8 | EX42: 8 | EY42: 8 | EZ42: 8 | FA42: 8 | FB42: 8 | FC42: 8 | FD42: 8 | FE42: 8 | FF42: 8 | FG42: 8 | FH42: 8 | FI42: 8 | FJ42: 8 | FK42: 8 | FL42: 8 | FM42: 8 | FN42: 8 | FO42: 8 | FP42: 8 | FQ42: 8 | FR42: 8 | FS42: 8 | FT42: 8 | FU42: 8 | FV42: 8 | FW42: 8 | FX42: 8 | FY42: 8 | FZ42: 8 | GA42: 8 | GB42: 8 | GC42: 8 | GD42: 8 | GE42: 8 | GF42: 8 | GG42: 8 | GH42: 8 | GI42: 8 | GJ42: 8 | GK42: 8 | GL42: 8 | GM42: 8 | GN42: 8 | GO42: 8 | GP42: 8 | GQ42: 8 | GR42: 8 | GS42: 8 | GT42: 8
B43: - NETFLIX | C43: =SUM(V43:AG43) -> 191.88 | D43: =SUM(AH43:AS43) -> 175.88 | E43: =SUM(AT43:BE43) -> 87.89 | F43: =SUM(BF43:BQ43) -> 95.88 | G43: =SUM(BR43:CC43) -> 95.88 | H43: =SUM(CD43:CO43) -> 86.88 | I43: =SUM(CP43:DA43) -> 83.88 | K43: =C43/12 -> 15.99 | L43: =D43/12 -> 14.656667 | M43: =E43/12 -> 7.3241667 | N43: =F43/12 -> 7.99 | O43: =G43/12 -> 7.99 | P43: =H43/12 -> 7.24 | Q43: =I43/12 -> 6.99 | S43: 15.99 | T43: 15.99 | U43: 15.99 | V43: 15.99 | W43: 15.99 | X43: 15.99 | Y43: 15.99 | Z43: 15.99 | AA43: 15.99 | AB43: 15.99 | AC43: 15.99 | AD43: 15.99 | AE43: 15.99 | AF43: 15.99 | AG43: 15.99 | AH43: 15.99 | AI43: 15.99 | AJ43: 15.99 | AK43: 15.99 | AL43: 15.99 | AM43: 15.99 | AN43: 15.99 | AO43: 15.99 | AP43: 15.99 | AQ43: 11.99 | AR43: 11.99 | AS43: 7.99 | AU43: 7.99 | AV43: 7.99 | AW43: 7.99 | AX43: 7.99 | AY43: 7.99 | AZ43: 7.99 | BA43: 7.99 | BB43: 7.99 | BC43: 7.99 | BD43: 7.99 | BE43: 7.99 | BF43: 7.99 | BG43: 7.99 | BH43: 7.99 | BI43: 7.99 | BJ43: 7.99 | BK43: 7.99 | BL43: 7.99 | BM43: 7.99 | BN43: 7.99 | BO43: 7.99 | BP43: 7.99 | BQ43: 7.99 | BR43: 7.99 | BS43: 7.99 | BT43: 7.99 | BU43: 7.99 | BV43: 7.99 | BW43: 7.99 | BX43: 7.99 | BY43: 7.99 | BZ43: 7.99 | CA43: 7.99 | CB43: 7.99 | CC43: 7.99 | CD43: 9.99 | CE43: 6.99 | CF43: 6.99 | CG43: 6.99 | CH43: 6.99 | CI43: 6.99 | CJ43: 6.99 | CK43: 6.99 | CL43: 6.99 | CM43: 6.99 | CN43: 6.99 | CO43: 6.99 | CP43: 6.99 | CQ43: 6.99 | CR43: 6.99 | CS43: 6.99 | CT43: 6.99 | CU43: 6.99 | CV43: 6.99 | CW43: 6.99 | CX43: 6.99 | CY43: 6.99 | CZ43: 6.99 | DA43: 6.99 | DB43: 6.99 | DC43: 6.99 | DD43: 6.99 | DE43: 6.99 | DF43: 6.99 | DG43: 6.99 | DH43: 6.99 | DI43: 6.99 | DJ43: 6.99 | DK43: 6.99 | DL43: 6.99 | DM43: 6.99 | DN43: 6.99 | DO43: 6.99 | DP43: 6.99 | DQ43: 6.99 | DR43: 6.99 | DS43: 6.99 | DT43: 6.99 | DU43: 6.99 | DV43: 6.99 | DW43: 6.99 | DX43: 6.99 | DY43: 6.99 | DZ43: 6.99 | EA43: 6.99 | EB43: 6.99 | EC43: 6.99 | ED43: 6.99 | EE43: 6.99 | EF43: 6.99 | EG43: 6.99 | EH43: 6.99 | EI43: 6.99 | EJ43: 6.99 | EK43: 6.99 | EL43: 6.99 | EM43: 6.99 | EN43: 6.99 | EO43: 6.99 | EP43: 6.99 | EQ43: 6.99 | ER43: 6.99 | ES43: 6.99 | ET43: 6.99 | EU43: 6.99 | EV43: 6.99 | EW43: 6.99 | EX43: 6.99 | EY43: 6.99 | EZ43: 6.99 | FA43: 6.99 | FB43: 6.99 | FC43: 6.99 | FD43: 6.99 | FE43: 6.99 | FF43: 6.99 | FG43: 6.99 | FH43: 6.99 | FI43: 6.99 | FJ43: 6.99 | FK43: 6.99 | FL43: 6.99 | FM43: 6.99 | FN43: 6.99 | FO43: 6.99 | FP43: 6.99 | FQ43: 6.99 | FR43: 6.99 | FS43: 6.99 | FT43: 6.99 | FU43: 6.99 | FV43: 6.99 | FW43: 6.99 | FX43: 6.99 | FY43: 6.99 | FZ43: 6.99 | GA43: 6.99 | GB43: 6.99 | GC43: 6.99 | GD43: 6.99 | GE43: 6.99 | GF43: 6.99 | GG43: 6.99 | GH43: 6.99 | GI43: 6.99 | GJ43: 6.99 | GK43: 6.99 | GL43: 6.99 | GM43: 6.99 | GN43: 6.99 | GO43: 6.99 | GP43: 6.99 | GQ43: 6.99 | GR43: 6.99 | GS43: 6.99 | GT43: 6.99
...

Sheet PRELIEVI CONTANTI
A1: DATA | B1: ANNO | C1: MESE | D1: PRELIEVO CONTO | E1: PRELIEVO CARTA | F1: INTERESSI | G1: TOTALE MESE | I1: RIEPILOGO ANNUALE PRELIEVI
A2: 43709 | B2: =YEAR(A2) -> 2019 | C2: =MONTH(A2) -> 9 | D2: 0 | E2: =BILANCIO!S58 -> 340 | F2: =8+2.8+2.8 -> 13.6 | G2: =D2+E2+F2 -> 353.6 | I2: ANNO | J2: CARTA CREDITO | K2: INTERESSI | L2: CONTO BANCA | M2: TOTALE | N2: DIFF. ANNO PREC. | O2: VAR. %
A3: 43739 | B3: =YEAR(A3) -> 2019 | C3: =MONTH(A3) -> 10 | D3: =BILANCIO!S24 -> 0 | E3: =BILANCIO!T58 -> 490 | F3: =3.2+2.8+4+2.8+4+2.8 -> 19.6 | G3: =D3+E3+F3 -> 509.6 | I3: 2019 | J3: =SUMIF($B:$B,I3,$E:$E) -> 1470 | K3: =SUMIF($B:$B,I3,$F:$F) -> 58.8 | L3: =SUMIF($B:$B,I3,$D:$D) -> 0 | M3: =J3+K3+L3 -> 1528.8 | N3: - | O3: -
A4: 43770 | B4: =YEAR(A4) -> 2019 | C4: =MONTH(A4) -> 11 | D4: =BILANCIO!T24 -> 0 | E4: =BILANCIO!U58 -> 400 | F4: =4+8+4 -> 16 | G4: =D4+E4+F4 -> 416 | I4: 2020 | J4: =SUMIF($B:$B,I4,$E:$E) -> 2680 | K4: =SUMIF($B:$B,I4,$F:$F) -> 103.2 | L4: =SUMIF($B:$B,I4,$D:$D) -> 0 | M4: =J4+K4+L4 -> 2783.2 | N4: =M4-M3 -> 1254.4 | O4: =IF(M3=0,"-",(M4-M3)/M3) -> 0.82051282
A5: 43800 | B5: =YEAR(A5) -> 2019 | C5: =MONTH(A5) -> 12 | D5: =BILANCIO!U24 -> 0 | E5: =BILANCIO!V58 -> 240 | F5: =3.6+6 -> 9.6 | G5: =D5+E5+F5 -> 249.6 | I5: 2021 | J5: =SUMIF($B:$B,I5,$E:$E) -> 3284.91 | K5: =SUMIF($B:$B,I5,$F:$F) -> 134.04 | L5: =SUMIF($B:$B,I5,$D:$D) -> 3652 | M5: =J5+K5+L5 -> 7070.95 | N5: =M5-M4 -> 4287.75 | O5: =IF(M4=0,"-",(M5-M4)/M4) -> 1.5405828
A6: 43831 | B6: =YEAR(A6) -> 2020 | C6: =MONTH(A6) -> 1 | D6: =BILANCIO!V24 -> 0 | E6: =BILANCIO!W58 -> 220 | F6: =4.8+4 -> 8.8 | G6: =D6+E6+F6 -> 228.8 | I6: 2022 | J6: =SUMIF($B:$B,I6,$E:$E) -> 4271.79 | K6: =SUMIF($B:$B,I6,$F:$F) -> 192.46 | L6: =SUMIF($B:$B,I6,$D:$D) -> 1980 | M6: =J6+K6+L6 -> 6444.25 | N6: =M6-M5 -> -626.7 | O6: =IF(M5=0,"-",(M6-M5)/M5) -> -0.088630241
A7: 43862 | B7: =YEAR(A7) -> 2020 | C7: =MONTH(A7) -> 2 | D7: =BILANCIO!W24 -> 0 | E7: =BILANCIO!X58 -> 300 | F7: =4+4 -> 8 | G7: =D7+E7+F7 -> 308 | I7: 2023 | J7: =SUMIF($B:$B,I7,$E:$E) -> 4930 | K7: =SUMIF($B:$B,I7,$F:$F) -> 196.91 | L7: =SUMIF($B:$B,I7,$D:$D) -> 220 | M7: =J7+K7+L7 -> 5346.91 | N7: =M7-M6 -> -1097.34 | O7: =IF(M6=0,"-",(M7-M6)/M6) -> -0.17028203
A8: 43891 | B8: =YEAR(A8) -> 2020 | C8: =MONTH(A8) -> 3 | D8: =BILANCIO!X24 -> 0 | E8: =BILANCIO!Y58 -> 0 | G8: =D8+E8+F8 -> 0 | I8: 2024 | J8: =SUMIF($B:$B,I8,$E:$E) -> 3232.9 | K8: =SUMIF($B:$B,I8,$F:$F) -> 128.93 | L8: =SUMIF($B:$B,I8,$D:$D) -> 442 | M8: =J8+K8+L8 -> 3803.83 | N8: =M8-M7 -> -1543.08 | O8: =IF(M7=0,"-",(M8-M7)/M7) -> -0.28859285
A9: 43922 | B9: =YEAR(A9) -> 2020 | C9: =MONTH(A9) -> 4 | D9: =BILANCIO!Y24 -> 0 | E9: =BILANCIO!Z58 -> 0 | G9: =D9+E9+F9 -> 0 | I9: 2025 | J9: =SUMIF($B:$B,I9,$E:$E) -> 1100 | K9: =SUMIF($B:$B,I9,$F:$F) -> 42.07 | L9: =SUMIF($B:$B,I9,$D:$D) -> 1030 | M9: =J9+K9+L9 -> 2172.07 | N9: =M9-M8 -> -1631.76 | O9: =IF(M8=0,"-",(M9-M8)/M8) -> -0.42897816
A10: 43952 | B10: =YEAR(A10) -> 2020 | C10: =MONTH(A10) -> 5 | D10: =BILANCIO!Z24 -> 0 | E10: =BILANCIO!AA58 -> 150 | F10: 6 | G10: =D10+E10+F10 -> 156 | I10: 2026 | J10: =SUMIF($B:$B,I10,$E:$E) -> 80 | K10: =SUMIF($B:$B,I10,$F:$F) -> 3.2 | L10: =SUMIF($B:$B,I10,$D:$D) -> 1466 | M10: =J10+K10+L10 -> 1549.2 | N10: =M10-M9 -> -622.87 | O10: =IF(M9=0,"-",(M10-M9)/M9) -> -0.28676332
A11: 43983 | B11: =YEAR(A11) -> 2020 | C11: =MONTH(A11) -> 6 | D11: =BILANCIO!AA24 -> 0 | E11: =BILANCIO!AB58 -> 200 | F11: =4+4 -> 8 | G11: =D11+E11+F11 -> 208 | I11: 2027 | J11: =SUMIF($B:$B,I11,$E:$E) -> 0 | K11: =SUMIF($B:$B,I11,$F:$F) -> 0 | L11: =SUMIF($B:$B,I11,$D:$D) -> 0 | M11: =J11+K11+L11 -> 0 | N11: =M11-M10 -> -1549.2 | O11: =IF(M10=0,"-",(M11-M10)/M10) -> -1
A12: 44013 | B12: =YEAR(A12) -> 2020 | C12: =MONTH(A12) -> 7 | D12: =BILANCIO!AB24 -> 0 | E12: =BILANCIO!AC58 -> 200 | F12: =4+4 -> 8 | G12: =D12+E12+F12 -> 208 | I12: 2028 | J12: =SUMIF($B:$B,I12,$E:$E) -> 0 | K12: =SUMIF($B:$B,I12,$F:$F) -> 0 | L12: =SUMIF($B:$B,I12,$D:$D) -> 0 | M12: =J12+K12+L12 -> 0 | N12: =M12-M11 -> 0 | O12: =IF(M11=0,"-",(M12-M11)/M11) -> -
A13: 44044 | B13: =YEAR(A13) -> 2020 | C13: =MONTH(A13) -> 8 | D13: =BILANCIO!AC24 -> 0 | E13: =BILANCIO!AD58 -> 340 | F13: =2.8+2.8+4+4 -> 13.6 | G13: =D13+E13+F13 -> 353.6 | I13: 2029 | J13: =SUMIF($B:$B,I13,$E:$E) -> 0 | K13: =SUMIF($B:$B,I13,$F:$F) -> 0 | L13: =SUMIF($B:$B,I13,$D:$D) -> 0 | M13: =J13+K13+L13 -> 0 | N13: =M13-M12 -> 0 | O13: =IF(M12=0,"-",(M13-M12)/M12) -> -
A14: 44075 | B14: =YEAR(A14) -> 2020 | C14: =MONTH(A14) -> 9 | D14: =BILANCIO!AD24 -> 0 | E14: =BILANCIO!AE58 -> 350 | F14: =4+4+6 -> 14 | G14: =D14+E14+F14 -> 364 | I14: TOTALE | J14: =SUM(J3:J13) -> 21049.6 | K14: =SUM(K3:K13) -> 859.61 | L14: =SUM(L3:L13) -> 8790 | M14: =SUM(M3:M13) -> 30699.21
A15: 44105 | B15: =YEAR(A15) -> 2020 | C15: =MONTH(A15) -> 10 | D15: =BILANCIO!AE24 -> 0 | E15: =BILANCIO!AF58 -> 340 | F15: =5.6+4+4 -> 13.6 | G15: =D15+E15+F15 -> 353.6
A16: 44136 | B16: =YEAR(A16) -> 2020 | C16: =MONTH(A16) -> 11 | D16: =BILANCIO!AF24 -> 0 | E16: =BILANCIO!AG58 -> 430 | F16: =2.8+11.6+2.8 -> 17.2 | G16: =D16+E16+F16 -> 447.2
A17: 44166 | B17: =YEAR(A17) -> 2020 | C17: =MONTH(A17) -> 12 | D17: =BILANCIO!AG24 -> 0 | E17: =BILANCIO!AH58 -> 150 | F17: 6 | G17: =D17+E17+F17 -> 156
A18: 44197 | B18: =YEAR(A18) -> 2021 | C18: =MONTH(A18) -> 1 | D18: =BILANCIO!AH24 -> 0 | E18: =BILANCIO!AI58 -> 100 | F18: 4 | G18: =D18+E18+F18 -> 104
A19: 44228 | B19: =YEAR(A19) -> 2021 | C19: =MONTH(A19) -> 2 | D19: =BILANCIO!AI24 -> 0 | E19: =BILANCIO!AJ58 -> 390 | F19: =2.8+10+2.8 -> 15.6 | G19: =D19+E19+F19 -> 405.6
A20: 44256 | B20: =YEAR(A20) -> 2021 | C20: =MONTH(A20) -> 3 | D20: =BILANCIO!AJ24 -> 2100 | E20: =BILANCIO!AK58 -> 0 | G20: =D20+E20+F20 -> 2100
